Workbook
Name CostScreen: _xlfn.LAMBDA(_xlpm.CostBrut,IFERROR(ROUND(_xlpm.CostBrut/CHOOSE(INT((LEN(_xlpm.CostBrut)-1)/3)+1,1,1000,1000000,1000000000),2) & CHOOSE(INT((LEN(_xlpm.CostBrut)-1)/3)+1,"","K","M","B"),""))
Name GetMutationLevel: _xlfn.LAMBDA(_xlpm.palname,IF(IFERROR(VLOOKUP(_xlpm.palname,_xlfn.CHOOSECOLS(PalmonList,34),1,FALSE),-1)>0,1,IF(IFERROR(VLOOKUP(_xlpm.palname,_xlfn.CHOOSECOLS(PalmonList,35),1,FALSE),-1)>0,2,"")))
Name HallLevel: Palmon!$C$50
Name IsBetween: _xlfn.LAMBDA(_xlpm.valeur,_xlpm.mini,_xlpm.maxi,AND(_xlpm.valeur<=_xlpm.maxi,_xlpm.valeur>=_xlpm.mini))
Name IsUpgradable: _xlfn.LAMBDA(_xlpm.level,IF(AND(_xlpm.level>0,_xlpm.level<HallLevel*10),1,""))
Name LevelUpgradeCost: _xlfn.LAMBDA(_xlpm.CurrentLevel,MAX(VLOOKUP(HallLevel*10,PalmonUpgradeCost,5,FALSE)-VLOOKUP(MAX(_xlpm.CurrentLevel-1,0),PalmonUpgradeCost,5,FALSE),0))
Name NeedsFull: Details!$D$9
Name PalmonList: Palmon!$B$3:$AK$47
Name PalmonListCols: Palmon!$B$2:$I$2
Name PalmonListWIthHeaders: Palmon!$B$2:$O$47
Name PalmonMutationCost: Tableaux!$N$2:$R$226
Name PalmonNames: _xlfn._xlws.SORT(Palmon!$B$3:$B$47)
Name PalmonNamesSorted: Tableaux!$U$3:$U$42
Name PalmonSkill: {"Attack";"Defend"}
Name PalmonUpgradeCost: Tableaux!$A$3:$F$302
Name StepNeeds: Details!$B$4:$E$8
Name TestNom: _xlfn._xlws.SORT(_xlfn._xlws.FILTER(Palmon!$B$3:$B$47,Palmon!$G$3:$G$47>0))

Sheet Palmon
B1: List | J1: Competency | P1: Stars | X1: Level | AA1: Team | AE1: Extra | AI1: Mutation
B2: Name | C2: Type | D2: Skill | E2: Level | F2: Upgradable | G2: Step | H2: Stars | I2: Stock | J2: 1 | K2: 2 | L2: 3 | M2: 4 | N2: 5 | P2: 1 | Q2: 2 | R2: 3 | S2: 4 | T2: 5 | U2: Achievement | V2: Needs | X2: Cost to max | Y2: Upgradable | AA2: RankPower | AB2: Rank | AC2: Team | AE2: URL | AF2: URL Mutation | AI2: 1 | AJ2: 2
A3: {=GetMutationLevel(B3)} -> 1 | B3: Bufonobi | C3: Water | D3: Attack | E3: 270 | F3: {=IsUpgradable(E3)} -> 1 | G3: =INT(H3) -> 5 | H3: 5 | I3: 0 | J3: 30 | K3: 30 | L3: 30 | M3: =IF($G3>3,"Max","") -> Max | N3: =IF(H3=5,10,"") -> 10 | P3: =IFERROR(CHOOSE(IF($H3>=Details!$B$4,1,2),Details!$D$4,IF($H3>Details!$B$4-1,IF($H3<1,$H3,MOD($H3,Details!$B$4-1))*10*Details!$C$4,""))/Details!$D$4,0) -> 1 | Q3: =IFERROR(CHOOSE(IF($H3>=Details!$B$5,1,2),Details!$D$5,IF($H3>Details!$B$5-1,IF($H3<1,Details!$G$4,MOD($H3,Details!$B$5-1))*10*Details!$C$5,""))/Details!$D$5,0) -> 1 | R3: =IFERROR(CHOOSE(IF($H3>=Details!$B$6,1,2),Details!$D$6,IF($H3>Details!$B$6-1,IF($H3<1,Details!$G$5,MOD($H3,Details!$B$6-1))*10*Details!$C$6,""))/Details!$D$6,0) -> 1 | S3: =IFERROR(CHOOSE(IF($H3>=Details!$B$7,1,2),Details!$D$7,IF($H3>Details!$B$7-1,IF($H3<1,Details!$G$5,MOD($H3,Details!$B$7-1))*10*Details!$C$7,""))/Details!$D$7,0) -> 1 | T3: =IFERROR(CHOOSE(IF($H3>=Details!$B$8,1,2),Details!$D$8,IF($H3>Details!$B$8-1,IF($H3<1,Details!$G$5,MOD($H3,Details!$B$8-1))*10*Details!$C$8,""))/Details!$D$8,0) -> 1 | U3: {=SUMPRODUCT(TRANSPOSE(Details!$D$4:$D$8),$P3:$T3)/Details!$D$9} -> 1 | V3: {=Details!$D$9-SUMPRODUCT(TRANSPOSE(Details!$D$4:$D$8),$P3:$T3)-$I3} -> 0 | X3: {=LevelUpgradeCost($E3)} -> 1515640000 | Y3: =F3 -> 1 | AA3: =$H3*1000+$E3 -> 5270 | AB3: =RANK($AA3,$AA$3:$AA$47)+COUNTIF($AA$3:$AA3,AA3)-1 -> 2 | AC3: {=IFERROR(_xlfn.IFS($AB3<8,1,$AB3<15,2,$AB3<21,3),"")} -> 1 | AE3: =AF23 -> https://encrypted-tbn0.gstatic.com/images?q=tbn:ANd9GcRXczs_Bjhslhr7Mf2HENU6MTyGpz0RJEMjNA&s | AF3: =" " | AG3: =" " | AJ3: Shadowkaeru
A4: {=GetMutationLevel(B4)} -> 1 | B4: Vulpyrean | C4: Fire | D4: Attack | E4: 270 | F4: {=IsUpgradable(E4)} -> 1 | G4: =INT(H4) -> 5 | H4: 5 | I4: 0 | J4: 20 | K4: 20 | L4: 20 | M4: =IF($G4>3,"Max","") -> Max | N4: =IF(H4=5,10,"") -> 10 | P4: =IFERROR(CHOOSE(IF($H4>=Details!$B$4,1,2),Details!$D$4,IF($H4>Details!$B$4-1,IF($H4<1,$H4,MOD($H4,Details!$B$4-1))*10*Details!$C$4,""))/Details!$D$4,0) -> 1 | Q4: =IFERROR(CHOOSE(IF($H4>=Details!$B$5,1,2),Details!$D$5,IF($H4>Details!$B$5-1,IF($H4<1,Details!$G$4,MOD($H4,Details!$B$5-1))*10*Details!$C$5,""))/Details!$D$5,0) -> 1 | R4: =IFERROR(CHOOSE(IF($H4>=Details!$B$6,1,2),Details!$D$6,IF($H4>Details!$B$6-1,IF($H4<1,Details!$G$5,MOD($H4,Details!$B$6-1))*10*Details!$C$6,""))/Details!$D$6,0) -> 1 | S4: =IFERROR(CHOOSE(IF($H4>=Details!$B$7,1,2),Details!$D$7,IF($H4>Details!$B$7-1,IF($H4<1,Details!$G$5,MOD($H4,Details!$B$7-1))*10*Details!$C$7,""))/Details!$D$7,0) -> 1 | T4: =IFERROR(CHOOSE(IF($H4>=Details!$B$8,1,2),Details!$D$8,IF($H4>Details!$B$8-1,IF($H4<1,Details!$G$5,MOD($H4,Details!$B$8-1))*10*Details!$C$8,""))/Details!$D$8,0) -> 1 | U4: {=SUMPRODUCT(TRANSPOSE(Details!$D$4:$D$8),$P4:$T4)/Details!$D$9} -> 1 | V4: {=Details!$D$9-SUMPRODUCT(TRANSPOSE(Details!$D$4:$D$8),$P4:$T4)-$I4} -> 0 | X4: {=LevelUpgradeCost($E4)} -> 1515640000 | Y4: =F4 -> 1 | AA4: =$H4*1000+$E4 -> 5270 | AB4: =RANK($AA4,$AA$3:$AA$47)+COUNTIF($AA$3:$AA4,AA4)-1 -> 3 | AC4: {=IFERROR(_xlfn.IFS($AB4<8,1,$AB4<15,2,$AB4<21,3),"")} -> 1 | AE4: https://encrypted-tbn0.gstatic.com/images?q=tbn:ANd9GcSDZWuq2tiKYc0zKRxpHXrLSMZ1GsY_6wEIYw&s | AF4: https://encrypted-tbn0.gstatic.com/images?q=tbn:ANd9GcRGF27Z8fOuiwM1qjDFQVY262gS_QKIJamMNg&s | AG4: =" "
A5: {=GetMutationLevel(B5)} | B5: Hoofrit | C5: Fire | D5: Attack | E5: 270 | F5: {=IsUpgradable(E5)} -> 1 | G5: =INT(H5) -> 4 | H5: 4 | I5: 11 | J5: 15 | K5: 15 | L5: 15 | M5: =IF($G5>3,"Max","") -> Max | N5: =IF(H5=5,10,"") | P5: =IFERROR(CHOOSE(IF($H5>=Details!$B$4,1,2),Details!$D$4,IF($H5>Details!$B$4-1,IF($H5<1,$H5,MOD($H5,Details!$B$4-1))*10*Details!$C$4,""))/Details!$D$4,0) -> 1 | Q5: =IFERROR(CHOOSE(IF($H5>=Details!$B$5,1,2),Details!$D$5,IF($H5>Details!$B$5-1,IF($H5<1,Details!$G$4,MOD($H5,Details!$B$5-1))*10*Details!$C$5,""))/Details!$D$5,0) -> 1 | R5: =IFERROR(CHOOSE(IF($H5>=Details!$B$6,1,2),Details!$D$6,IF($H5>Details!$B$6-1,IF($H5<1,Details!$G$5,MOD($H5,Details!$B$6-1))*10*Details!$C$6,""))/Details!$D$6,0) -> 1 | S5: =IFERROR(CHOOSE(IF($H5>=Details!$B$7,1,2),Details!$D$7,IF($H5>Details!$B$7-1,IF($H5<1,Details!$G$5,MOD($H5,Details!$B$7-1))*10*Details!$C$7,""))/Details!$D$7,0) -> 1 | T5: =IFERROR(CHOOSE(IF($H5>=Details!$B$8,1,2),Details!$D$8,IF($H5>Details!$B$8-1,IF($H5<1,Details!$G$5,MOD($H5,Details!$B$8-1))*10*Details!$C$8,""))/Details!$D$8,0) -> 0 | U5: {=SUMPRODUCT(TRANSPOSE(Details!$D$4:$D$8),$P5:$T5)/Details!$D$9} -> 0.48717949 | V5: {=Details!$D$9-SUMPRODUCT(TRANSPOSE(Details!$D$4:$D$8),$P5:$T5)-$I5} -> 489 | X5: {=LevelUpgradeCost($E5)} -> 1515640000 | Y5: =F5 -> 1 | AA5: =$H5*1000+$E5 -> 4270 | AB5: =RANK($AA5,$AA$3:$AA$47)+COUNTIF($AA$3:$AA5,AA5)-1 -> 13 | AC5: {=IFERROR(_xlfn.IFS($AB5<8,1,$AB5<15,2,$AB5<21,3),"")} -> 2 | AE5: https://encrypted-tbn0.gstatic.com/images?q=tbn:ANd9GcRwfHFWjB1bN67FJNyjjWvBJwviWJ3Tada0Yg&s | AF5: https://encrypted-tbn0.gstatic.com/images?q=tbn:ANd9GcSkOv6mOI5FaIAjcVgErYDwVaivkH3WdUQIzw&s | AG5: =" " | AI5: Flaries
A6: {=GetMutationLevel(B6)} | B6: Ghillant | C6: Wood | D6: Defend | E6: 250 | F6: {=IsUpgradable(E6)} -> 1 | G6: =INT(H6) -> 4 | H6: 4.1 | I6: 0 | J6: 5 | K6: 5 | L6: 5 | M6: =IF($G6>3,"Max","") -> Max | N6: =IF(H6=5,10,"") | P6: =IFERROR(CHOOSE(IF($H6>=Details!$B$4,1,2),Details!$D$4,IF($H6>Details!$B$4-1,IF($H6<1,$H6,MOD($H6,Details!$B$4-1))*10*Details!$C$4,""))/Details!$D$4,0) -> 1 | Q6: =IFERROR(CHOOSE(IF($H6>=Details!$B$5,1,2),Details!$D$5,IF($H6>Details!$B$5-1,IF($H6<1,Details!$G$4,MOD($H6,Details!$B$5-1))*10*Details!$C$5,""))/Details!$D$5,0) -> 1 | R6: =IFERROR(CHOOSE(IF($H6>=Details!$B$6,1,2),Details!$D$6,IF($H6>Details!$B$6-1,IF($H6<1,Details!$G$5,MOD($H6,Details!$B$6-1))*10*Details!$C$6,""))/Details!$D$6,0) -> 1 | S6: =IFERROR(CHOOSE(IF($H6>=Details!$B$7,1,2),Details!$D$7,IF($H6>Details!$B$7-1,IF($H6<1,Details!$G$5,MOD($H6,Details!$B$7-1))*10*Details!$C$7,""))/Details!$D$7,0) -> 1 | T6: =IFERROR(CHOOSE(IF($H6>=Details!$B$8,1,2),Details!$D$8,IF($H6>Details!$B$8-1,IF($H6<1,Details!$G$5,MOD($H6,Details!$B$8-1))*10*Details!$C$8,""))/Details!$D$8,0) -> 0.2 | U6: {=SUMPRODUCT(TRANSPOSE(Details!$D$4:$D$8),$P6:$T6)/Details!$D$9} -> 0.58974359 | V6: {=Details!$D$9-SUMPRODUCT(TRANSPOSE(Details!$D$4:$D$8),$P6:$T6)-$I6} -> 400 | X6: {=LevelUpgradeCost($E6)} -> 3503540000 | Y6: =F6 -> 1 | AA6: =$H6*1000+$E6 -> 4350 | AB6: =RANK($AA6,$AA$3:$AA$47)+COUNTIF($AA$3:$AA6,AA6)-1 -> 10 | AC6: {=IFERROR(_xlfn.IFS($AB6<8,1,$AB6<15,2,$AB6<21,3),"")} -> 2 | AE6: https://encrypted-tbn0.gstatic.com/images?q=tbn:ANd9GcQOwDXppnwkCtCXXAqUiiNMhf6T-lane54jPg&s | AF6: =" " | AG6: =" " | AI6: Chefeuillier
A7: {=GetMutationLevel(B7)} -> 1 | B7: Gnashfin | C7: Water | D7: Defend | E7: 270 | F7: {=IsUpgradable(E7)} -> 1 | G7: =INT(H7) -> 5 | H7: 5 | I7: 0 | J7: 15 | K7: 20 | L7: 30 | M7: =IF($G7>3,"Max","") -> Max | N7: =IF(H7=5,10,"") -> 10 | P7: =IFERROR(CHOOSE(IF($H7>=Details!$B$4,1,2),Details!$D$4,IF($H7>Details!$B$4-1,IF($H7<1,$H7,MOD($H7,Details!$B$4-1))*10*Details!$C$4,""))/Details!$D$4,0) -> 1 | Q7: =IFERROR(CHOOSE(IF($H7>=Details!$B$5,1,2),Details!$D$5,IF($H7>Details!$B$5-1,IF($H7<1,Details!$G$4,MOD($H7,Details!$B$5-1))*10*Details!$C$5,""))/Details!$D$5,0) -> 1 | R7: =IFERROR(CHOOSE(IF($H7>=Details!$B$6,1,2),Details!$D$6,IF($H7>Details!$B$6-1,IF($H7<1,Details!$G$5,MOD($H7,Details!$B$6-1))*10*Details!$C$6,""))/Details!$D$6,0) -> 1 | S7: =IFERROR(CHOOSE(IF($H7>=Details!$B$7,1,2),Details!$D$7,IF($H7>Details!$B$7-1,IF($H7<1,Details!$G$5,MOD($H7,Details!$B$7-1))*10*Details!$C$7,""))/Details!$D$7,0) -> 1 | T7: =IFERROR(CHOOSE(IF($H7>=Details!$B$8,1,2),Details!$D$8,IF($H7>Details!$B$8-1,IF($H7<1,Details!$G$5,MOD($H7,Details!$B$8-1))*10*Details!$C$8,""))/Details!$D$8,0) -> 1 | U7: {=SUMPRODUCT(TRANSPOSE(Details!$D$4:$D$8),$P7:$T7)/Details!$D$9} -> 1 | V7: {=Details!$D$9-SUMPRODUCT(TRANSPOSE(Details!$D$4:$D$8),$P7:$T7)-$I7} -> 0 | X7: {=LevelUpgradeCost($E7)} -> 1515640000 | Y7: =F7 -> 1 | AA7: =$H7*1000+$E7 -> 5270 | AB7: =RANK($AA7,$AA$3:$AA$47)+COUNTIF($AA$3:$AA7,AA7)-1 -> 4 | AC7: {=IFERROR(_xlfn.IFS($AB7<8,1,$AB7<15,2,$AB7<21,3),"")} -> 1 | AE7: https://encrypted-tbn0.gstatic.com/images?q=tbn:ANd9GcTII6bAUVzdPfr_45Db3bGwDuIVxhe-n4dSSgHRGJaEpg&s | AF7: =" " | AG7: =" "
A8: {=GetMutationLevel(B8)} | B8: Gnashley | C8: Water | D8: Defend | E8: 1 | F8: {=IsUpgradable(E8)} -> 1 | G8: =INT(H8) -> 1 | H8: 1 | I8: 0 | J8: 1 | K8: 1 | L8: 1 | M8: =IF($G8>3,"Max","") | N8: =IF(H8=5,10,"") | P8: =IFERROR(CHOOSE(IF($H8>=Details!$B$4,1,2),Details!$D$4,IF($H8>Details!$B$4-1,IF($H8<1,$H8,MOD($H8,Details!$B$4-1))*10*Details!$C$4,""))/Details!$D$4,0) -> 1 | Q8: =IFERROR(CHOOSE(IF($H8>=Details!$B$5,1,2),Details!$D$5,IF($H8>Details!$B$5-1,IF($H8<1,Details!$G$4,MOD($H8,Details!$B$5-1))*10*Details!$C$5,""))/Details!$D$5,0) -> 0 | R8: =IFERROR(CHOOSE(IF($H8>=Details!$B$6,1,2),Details!$D$6,IF($H8>Details!$B$6-1,IF($H8<1,Details!$G$5,MOD($H8,Details!$B$6-1))*10*Details!$C$6,""))/Details!$D$6,0) -> 0 | S8: =IFERROR(CHOOSE(IF($H8>=Details!$B$7,1,2),Details!$D$7,IF($H8>Details!$B$7-1,IF($H8<1,Details!$G$5,MOD($H8,Details!$B$7-1))*10*Details!$C$7,""))/Details!$D$7,0) -> 0 | T8: =IFERROR(CHOOSE(IF($H8>=Details!$B$8,1,2),Details!$D$8,IF($H8>Details!$B$8-1,IF($H8<1,Details!$G$5,MOD($H8,Details!$B$8-1))*10*Details!$C$8,""))/Details!$D$8,0) -> 0 | U8: {=SUMPRODUCT(TRANSPOSE(Details!$D$4:$D$8),$P8:$T8)/Details!$D$9} -> 0.025641026 | V8: {=Details!$D$9-SUMPRODUCT(TRANSPOSE(Details!$D$4:$D$8),$P8:$T8)-$I8} -> 950 | X8: {=LevelUpgradeCost($E8)} -> 6424613700 | Y8: =F8 -> 1 | AA8: =$H8*1000+$E8 -> 1001 | AB8: =RANK($AA8,$AA$3:$AA$47)+COUNTIF($AA$3:$AA8,AA8)-1 -> 32 | AC8: {=IFERROR(_xlfn.IFS($AB8<8,1,$AB8<15,2,$AB8<21,3),"")} | AE8: https://encrypted-tbn0.gstatic.com/images?q=tbn:ANd9GcQtrOr7ePo-_tg085QaHk6NorM32ywE44672A&s | AF8: https://encrypted-tbn0.gstatic.com/images?q=tbn:ANd9GcTII6bAUVzdPfr_45Db3bGwDuIVxhe-n4dSSgHRGJaEpg&s | AG8: =" " | AI8: Gnashfin
A9: {=GetMutationLevel(B9)} | B9: Magmolin | C9: Fire | D9: Defend | E9: 240 | F9: {=IsUpgradable(E9)} -> 1 | G9: =INT(H9) -> 3 | H9: 3.1 | I9: 61 | J9: 10 | K9: 5 | L9: 15 | M9: =IF($G9>3,"Max","") | N9: =IF(H9=5,10,"") | P9: =IFERROR(CHOOSE(IF($H9>=Details!$B$4,1,2),Details!$D$4,IF($H9>Details!$B$4-1,IF($H9<1,$H9,MOD($H9,Details!$B$4-1))*10*Details!$C$4,""))/Details!$D$4,0) -> 1 | Q9: =IFERROR(CHOOSE(IF($H9>=Details!$B$5,1,2),Details!$D$5,IF($H9>Details!$B$5-1,IF($H9<1,Details!$G$4,MOD($H9,Details!$B$5-1))*10*Details!$C$5,""))/Details!$D$5,0) -> 1 | R9: =IFERROR(CHOOSE(IF($H9>=Details!$B$6,1,2),Details!$D$6,IF($H9>Details!$B$6-1,IF($H9<1,Details!$G$5,MOD($H9,Details!$B$6-1))*10*Details!$C$6,""))/Details!$D$6,0) -> 1 | S9: =IFERROR(CHOOSE(IF($H9>=Details!$B$7,1,2),Details!$D$7,IF($H9>Details!$B$7-1,IF($H9<1,Details!$G$5,MOD($H9,Details!$B$7-1))*10*Details!$C$7,""))/Details!$D$7,0) -> 0.2 | T9: =IFERROR(CHOOSE(IF($H9>=Details!$B$8,1,2),Details!$D$8,IF($H9>Details!$B$8-1,IF($H9<1,Details!$G$5,MOD($H9,Details!$B$8-1))*10*Details!$C$8,""))/Details!$D$8,0) -> 0 | U9: {=SUMPRODUCT(TRANSPOSE(Details!$D$4:$D$8),$P9:$T9)/Details!$D$9} -> 0.24102564 | V9: {=Details!$D$9-SUMPRODUCT(TRANSPOSE(Details!$D$4:$D$8),$P9:$T9)-$I9} -> 679 | X9: {=LevelUpgradeCost($E9)} -> 4211940000 | Y9: =F9 -> 1 | AA9: =$H9*1000+$E9 -> 3340 | AB9: =RANK($AA9,$AA$3:$AA$47)+COUNTIF($AA$3:$AA9,AA9)-1 -> 16 | AC9: {=IFERROR(_xlfn.IFS($AB9<8,1,$AB9<15,2,$AB9<21,3),"")} -> 3 | AE9: https://encrypted-tbn0.gstatic.com/images?q=tbn:ANd9GcRebc6KbOAxblleg_L3rr2K13bt-Yyzq1bAaw&s | AF9: =" " | AG9: =" " | AI9: Obsidrake
A10: {=GetMutationLevel(B10)} | B10: Limudroid | C10: Electricity | D10: Attack | E10: 230 | F10: {=IsUpgradable(E10)} -> 1 | G10: =INT(H10) -> 2 | H10: 2.2 | I10: 4 | J10: 1 | K10: 1 | L10: 5 | M10: =IF($G10>3,"Max","") | N10: =IF(H10=5,10,"") | P10: =IFERROR(CHOOSE(IF($H10>=Details!$B$4,1,2),Details!$D$4,IF($H10>Details!$B$4-1,IF($H10<1,$H10,MOD($H10,Details!$B$4-1))*10*Details!$C$4,""))/Details!$D$4,0) -> 1 | Q10: =IFERROR(CHOOSE(IF($H10>=Details!$B$5,1,2),Details!$D$5,IF($H10>Details!$B$5-1,IF($H10<1,Details!$G$4,MOD($H10,Details!$B$5-1))*10*Details!$C$5,""))/Details!$D$5,0) -> 1 | R10: =IFERROR(CHOOSE(IF($H10>=Details!$B$6,1,2),Details!$D$6,IF($H10>Details!$B$6-1,IF($H10<1,Details!$G$5,MOD($H10,Details!$B$6-1))*10*Details!$C$6,""))/Details!$D$6,0) -> 0.4 | S10: =IFERROR(CHOOSE(IF($H10>=Details!$B$7,1,2),Details!$D$7,IF($H10>Details!$B$7-1,IF($H10<1,Details!$G$5,MOD($H10,Details!$B$7-1))*10*Details!$C$7,""))/Details!$D$7,0) -> 0 | T10: =IFERROR(CHOOSE(IF($H10>=Details!$B$8,1,2),Details!$D$8,IF($H10>Details!$B$8-1,IF($H10<1,Details!$G$5,MOD($H10,Details!$B$8-1))*10*Details!$C$8,""))/Details!$D$8,0) -> 0 | U10: {=SUMPRODUCT(TRANSPOSE(Details!$D$4:$D$8),$P10:$T10)/Details!$D$9} -> 0.11794872 | V10: {=Details!$D$9-SUMPRODUCT(TRANSPOSE(Details!$D$4:$D$8),$P10:$T10)-$I10} -> 856 | X10: {=LevelUpgradeCost($E10)} -> 4771140000 | Y10: =F10 -> 1 | AA10: =$H10*1000+$E10 -> 2430 | AB10: =RANK($AA10,$AA$3:$AA$47)+COUNTIF($AA$3:$AA10,AA10)-1 -> 28 | AC10: {=IFERROR(_xlfn.IFS($AB10<8,1,$AB10<15,2,$AB10<21,3),"")} | AE10: https://encrypted-tbn0.gstatic.com/images?q=tbn:ANd9GcQzaI21taP2V17MKjiPAeulm4V9qfST4umPdg&s | AF10: https://encrypted-tbn0.gstatic.com/images?q=tbn:ANd9GcRMlruQNUenhVk-fAEq9d3Wi8zw--0GbkLGJrX1CuQ1&s | AG10: =" " | AI10: Bunodroid
A11: {=GetMutationLevel(B11)} | B11: Barkplug | C11: Electricity | D11: Defend | E11: 250 | F11: {=IsUpgradable(E11)} -> 1 | G11: =INT(H11) -> 3 | H11: 3 | I11: 0 | J11: 14 | K11: 5 | L11: 10 | M11: =IF($G11>3,"Max","") | N11: =IF(H11=5,10,"") | P11: =IFERROR(CHOOSE(IF($H11>=Details!$B$4,1,2),Details!$D$4,IF($H11>Details!$B$4-1,IF($H11<1,$H11,MOD($H11,Details!$B$4-1))*10*Details!$C$4,""))/Details!$D$4,0) -> 1 | Q11: =IFERROR(CHOOSE(IF($H11>=Details!$B$5,1,2),Details!$D$5,IF($H11>Details!$B$5-1,IF($H11<1,Details!$G$4,MOD($H11,Details!$B$5-1))*10*Details!$C$5,""))/Details!$D$5,0) -> 1 | R11: =IFERROR(CHOOSE(IF($H11>=Details!$B$6,1,2),Details!$D$6,IF($H11>Details!$B$6-1,IF($H11<1,Details!$G$5,MOD($H11,Details!$B$6-1))*10*Details!$C$6,""))/Details!$D$6,0) -> 1 | S11: =IFERROR(CHOOSE(IF($H11>=Details!$B$7,1,2),Details!$D$7,IF($H11>Details!$B$7-1,IF($H11<1,Details!$G$5,MOD($H11,Details!$B$7-1))*10*Details!$C$7,""))/Details!$D$7,0) -> 0 | T11: =IFERROR(CHOOSE(IF($H11>=Details!$B$8,1,2),Details!$D$8,IF($H11>Details!$B$8-1,IF($H11<1,Details!$G$5,MOD($H11,Details!$B$8-1))*10*Details!$C$8,""))/Details!$D$8,0) -> 0 | U11: {=SUMPRODUCT(TRANSPOSE(Details!$D$4:$D$8),$P11:$T11)/Details!$D$9} -> 0.17948718 | V11: {=Details!$D$9-SUMPRODUCT(TRANSPOSE(Details!$D$4:$D$8),$P11:$T11)-$I11} -> 800 | X11: {=LevelUpgradeCost($E11)} -> 3503540000 | Y11: =F11 -> 1 | AA11: =$H11*1000+$E11 -> 3250 | AB11: =RANK($AA11,$AA$3:$AA$47)+COUNTIF($AA$3:$AA11,AA11)-1 -> 18 | AC11: {=IFERROR(_xlfn.IFS($AB11<8,1,$AB11<15,2,$AB11<21,3),"")} -> 3 | AE11: https://encrypted-tbn0.gstatic.com/images?q=tbn:ANd9GcSf59xsunrPEuFvdtBi-IRVMcrdBfW_vNshLA&s | AF11: https://encrypted-tbn0.gstatic.com/images?q=tbn:ANd9GcRUDpuK5BvjXDFqgMZvlxYadsaFFQDKOQrNCAHymiAy_w&s | AG11: =" " | AI11: Wattweiler
A12: {=GetMutationLevel(B12)} | B12: Abuzzinian | C12: Electricity | D12: Defend | E12: 250 | F12: {=IsUpgradable(E12)} -> 1 | G12: =INT(H12) -> 4 | H12: 4.1 | I12: 14 | J12: 1 | K12: 1 | L12: 1 | M12: =IF($G12>3,"Max","") -> Max | N12: =IF(H12=5,10,"") | P12: =IFERROR(CHOOSE(IF($H12>=Details!$B$4,1,2),Details!$D$4,IF($H12>Details!$B$4-1,IF($H12<1,$H12,MOD($H12,Details!$B$4-1))*10*Details!$C$4,""))/Details!$D$4,0) -> 1 | Q12: =IFERROR(CHOOSE(IF($H12>=Details!$B$5,1,2),Details!$D$5,IF($H12>Details!$B$5-1,IF($H12<1,Details!$G$4,MOD($H12,Details!$B$5-1))*10*Details!$C$5,""))/Details!$D$5,0) -> 1 | R12: =IFERROR(CHOOSE(IF($H12>=Details!$B$6,1,2),Details!$D$6,IF($H12>Details!$B$6-1,IF($H12<1,Details!$G$5,MOD($H12,Details!$B$6-1))*10*Details!$C$6,""))/Details!$D$6,0) -> 1 | S12: =IFERROR(CHOOSE(IF($H12>=Details!$B$7,1,2),Details!$D$7,IF($H12>Details!$B$7-1,IF($H12<1,Details!$G$5,MOD($H12,Details!$B$7-1))*10*Details!$C$7,""))/Details!$D$7,0) -> 1 | T12: =IFERROR(CHOOSE(IF($H12>=Details!$B$8,1,2),Details!$D$8,IF($H12>Details!$B$8-1,IF($H12<1,Details!$G$5,MOD($H12,Details!$B$8-1))*10*Details!$C$8,""))/Details!$D$8,0) -> 0.2 | U12: {=SUMPRODUCT(TRANSPOSE(Details!$D$4:$D$8),$P12:$T12)/Details!$D$9} -> 0.58974359 | V12: {=Details!$D$9-SUMPRODUCT(TRANSPOSE(Details!$D$4:$D$8),$P12:$T12)-$I12} -> 386 | X12: {=LevelUpgradeCost($E12)} -> 3503540000 | Y12: =F12 -> 1 | AA12: =$H12*1000+$E12 -> 4350 | AB12: =RANK($AA12,$AA$3:$AA$47)+COUNTIF($AA$3:$AA12,AA12)-1 -> 11 | AC12: {=IFERROR(_xlfn.IFS($AB12<8,1,$AB12<15,2,$AB12<21,3),"")} -> 2 | AE12: https://encrypted-tbn0.gstatic.com/images?q=tbn:ANd9GcT-r6BZKxjf-kMlCmzHjhnUHjvmCaOn5DxiYw&s | AF12: https://encrypted-tbn0.gstatic.com/images?q=tbn:ANd9GcR23XO-FCNYoHOIhLnxge8AzFmdP8mD1D-mzQ&s | AG12: =" " | AI12: Servolt
A13: {=GetMutationLevel(B13)} | B13: Escarffier | C13: Fire | D13: Defend | E13: 240 | F13: {=IsUpgradable(E13)} -> 1 | G13: =INT(H13) -> 2 | H13: 2.4 | I13: 8 | J13: 5 | K13: 5 | L13: 5 | M13: =IF($G13>3,"Max","") | N13: =IF(H13=5,10,"") | P13: =IFERROR(CHOOSE(IF($H13>=Details!$B$4,1,2),Details!$D$4,IF($H13>Details!$B$4-1,IF($H13<1,$H13,MOD($H13,Details!$B$4-1))*10*Details!$C$4,""))/Details!$D$4,0) -> 1 | Q13: =IFERROR(CHOOSE(IF($H13>=Details!$B$5,1,2),Details!$D$5,IF($H13>Details!$B$5-1,IF($H13<1,Details!$G$4,MOD($H13,Details!$B$5-1))*10*Details!$C$5,""))/Details!$D$5,0) -> 1 | R13: =IFERROR(CHOOSE(IF($H13>=Details!$B$6,1,2),Details!$D$6,IF($H13>Details!$B$6-1,IF($H13<1,Details!$G$5,MOD($H13,Details!$B$6-1))*10*Details!$C$6,""))/Details!$D$6,0) -> 0.8 | S13: =IFERROR(CHOOSE(IF($H13>=Details!$B$7,1,2),Details!$D$7,IF($H13>Details!$B$7-1,IF($H13<1,Details!$G$5,MOD($H13,Details!$B$7-1))*10*Details!$C$7,""))/Details!$D$7,0) -> 0 | T13: =IFERROR(CHOOSE(IF($H13>=Details!$B$8,1,2),Details!$D$8,IF($H13>Details!$B$8-1,IF($H13<1,Details!$G$5,MOD($H13,Details!$B$8-1))*10*Details!$C$8,""))/Details!$D$8,0) -> 0 | U13: {=SUMPRODUCT(TRANSPOSE(Details!$D$4:$D$8),$P13:$T13)/Details!$D$9} -> 0.15897436 | V13: {=Details!$D$9-SUMPRODUCT(TRANSPOSE(Details!$D$4:$D$8),$P13:$T13)-$I13} -> 812 | X13: {=LevelUpgradeCost($E13)} -> 4211940000 | Y13: =F13 -> 1 | AA13: =$H13*1000+$E13 -> 2640 | AB13: =RANK($AA13,$AA$3:$AA$47)+COUNTIF($AA$3:$AA13,AA13)-1 -> 22 | AC13: {=IFERROR(_xlfn.IFS($AB13<8,1,$AB13<15,2,$AB13<21,3),"")} | AE13: https://encrypted-tbn0.gstatic.com/images?q=tbn:ANd9GcST2CrUIPAlFNBLPgZn0Tu93KelabHVVAbNLQ&s | AF13: =" " | AG13: =" " | AI13: Essaucier
A14: {=GetMutationLevel(B14)} | B14: Lucidina | C14: Water | D14: Attack | E14: 270 | F14: {=IsUpgradable(E14)} -> 1 | G14: =INT(H14) -> 4 | H14: 4 | I14: 0 | J14: 5 | K14: 5 | L14: 15 | M14: =IF($G14>3,"Max","") -> Max | N14: =IF(H14=5,10,"") | P14: =IFERROR(CHOOSE(IF($H14>=Details!$B$4,1,2),Details!$D$4,IF($H14>Details!$B$4-1,IF($H14<1,$H14,MOD($H14,Details!$B$4-1))*10*Details!$C$4,""))/Details!$D$4,0) -> 1 | Q14: =IFERROR(CHOOSE(IF($H14>=Details!$B$5,1,2),Details!$D$5,IF($H14>Details!$B$5-1,IF($H14<1,Details!$G$4,MOD($H14,Details!$B$5-1))*10*Details!$C$5,""))/Details!$D$5,0) -> 1 | R14: =IFERROR(CHOOSE(IF($H14>=Details!$B$6,1,2),Details!$D$6,IF($H14>Details!$B$6-1,IF($H14<1,Details!$G$5,MOD($H14,Details!$B$6-1))*10*Details!$C$6,""))/Details!$D$6,0) -> 1 | S14: =IFERROR(CHOOSE(IF($H14>=Details!$B$7,1,2),Details!$D$7,IF($H14>Details!$B$7-1,IF($H14<1,Details!$G$5,MOD($H14,Details!$B$7-1))*10*Details!$C$7,""))/Details!$D$7,0) -> 1 | T14: =IFERROR(CHOOSE(IF($H14>=Details!$B$8,1,2),Details!$D$8,IF($H14>Details!$B$8-1,IF($H14<1,Details!$G$5,MOD($H14,Details!$B$8-1))*10*Details!$C$8,""))/Details!$D$8,0) -> 0 | U14: {=SUMPRODUCT(TRANSPOSE(Details!$D$4:$D$8),$P14:$T14)/Details!$D$9} -> 0.48717949 | V14: {=Details!$D$9-SUMPRODUCT(TRANSPOSE(Details!$D$4:$D$8),$P14:$T14)-$I14} -> 500 | X14: {=LevelUpgradeCost($E14)} -> 1515640000 | Y14: =F14 -> 1 | AA14: =$H14*1000+$E14 -> 4270 | AB14: =RANK($AA14,$AA$3:$AA$47)+COUNTIF($AA$3:$AA14,AA14)-1 -> 14 | AC14: {=IFERROR(_xlfn.IFS($AB14<8,1,$AB14<15,2,$AB14<21,3),"")} -> 2 | AE14: https://encrypted-tbn0.gstatic.com/images?q=tbn:ANd9GcR9A_xtftnwTH1zCnLIOcgmJKNZtFnB-e8QOw&s | AF14: =" " | AG14: =" " | AI14: Oneirina
A15: {=GetMutationLevel(B15)} -> 1 | B15: Fleurizard | C15: Wood | D15: Attack | E15: 270 | F15: {=IsUpgradable(E15)} -> 1 | G15: =INT(H15) -> 5 | H15: 5 | I15: 0 | J15: 1 | K15: 1 | L15: 1 | M15: =IF($G15>3,"Max","") -> Max | N15: =IF(H15=5,10,"") -> 10 | P15: =IFERROR(CHOOSE(IF($H15>=Details!$B$4,1,2),Details!$D$4,IF($H15>Details!$B$4-1,IF($H15<1,$H15,MOD($H15,Details!$B$4-1))*10*Details!$C$4,""))/Details!$D$4,0) -> 1 | Q15: =IFERROR(CHOOSE(IF($H15>=Details!$B$5,1,2),Details!$D$5,IF($H15>Details!$B$5-1,IF($H15<1,Details!$G$4,MOD($H15,Details!$B$5-1))*10*Details!$C$5,""))/Details!$D$5,0) -> 1 | R15: =IFERROR(CHOOSE(IF($H15>=Details!$B$6,1,2),Details!$D$6,IF($H15>Details!$B$6-1,IF($H15<1,Details!$G$5,MOD($H15,Details!$B$6-1))*10*Details!$C$6,""))/Details!$D$6,0) -> 1 | S15: =IFERROR(CHOOSE(IF($H15>=Details!$B$7,1,2),Details!$D$7,IF($H15>Details!$B$7-1,IF($H15<1,Details!$G$5,MOD($H15,Details!$B$7-1))*10*Details!$C$7,""))/Details!$D$7,0) -> 1 | T15: =IFERROR(CHOOSE(IF($H15>=Details!$B$8,1,2),Details!$D$8,IF($H15>Details!$B$8-1,IF($H15<1,Details!$G$5,MOD($H15,Details!$B$8-1))*10*Details!$C$8,""))/Details!$D$8,0) -> 1 | U15: {=SUMPRODUCT(TRANSPOSE(Details!$D$4:$D$8),$P15:$T15)/Details!$D$9} -> 1 | V15: {=Details!$D$9-SUMPRODUCT(TRANSPOSE(Details!$D$4:$D$8),$P15:$T15)-$I15} -> 0 | X15: {=LevelUpgradeCost($E15)} -> 1515640000 | Y15: =F15 -> 1 | AA15: =$H15*1000+$E15 -> 5270 | AB15: =RANK($AA15,$AA$3:$AA$47)+COUNTIF($AA$3:$AA15,AA15)-1 -> 5 | AC15: {=IFERROR(_xlfn.IFS($AB15<8,1,$AB15<15,2,$AB15<21,3),"")} -> 1 | AE15: https://encrypted-tbn0.gstatic.com/images?q=tbn:ANd9GcQCf63iS9oq-SMn3DO74UTS2j_zSrzNVTRMOQ&s | AF15: =" " | AG15: =" "
A16: {=GetMutationLevel(B16)} | B16: Statchew | C16: Wood | D16: Defend | E16: 250 | F16: {=IsUpgradable(E16)} -> 1 | G16: =INT(H16) -> 3 | H16: 3 | I16: 10 | J16: 15 | K16: 5 | L16: 9 | M16: =IF($G16>3,"Max","") | N16: =IF(H16=5,10,"") | P16: =IFERROR(CHOOSE(IF($H16>=Details!$B$4,1,2),Details!$D$4,IF($H16>Details!$B$4-1,IF($H16<1,$H16,MOD($H16,Details!$B$4-1))*10*Details!$C$4,""))/Details!$D$4,0) -> 1 | Q16: =IFERROR(CHOOSE(IF($H16>=Details!$B$5,1,2),Details!$D$5,IF($H16>Details!$B$5-1,IF($H16<1,Details!$G$4,MOD($H16,Details!$B$5-1))*10*Details!$C$5,""))/Details!$D$5,0) -> 1 | R16: =IFERROR(CHOOSE(IF($H16>=Details!$B$6,1,2),Details!$D$6,IF($H16>Details!$B$6-1,IF($H16<1,Details!$G$5,MOD($H16,Details!$B$6-1))*10*Details!$C$6,""))/Details!$D$6,0) -> 1 | S16: =IFERROR(CHOOSE(IF($H16>=Details!$B$7,1,2),Details!$D$7,IF($H16>Details!$B$7-1,IF($H16<1,Details!$G$5,MOD($H16,Details!$B$7-1))*10*Details!$C$7,""))/Details!$D$7,0) -> 0 | T16: =IFERROR(CHOOSE(IF($H16>=Details!$B$8,1,2),Details!$D$8,IF($H16>Details!$B$8-1,IF($H16<1,Details!$G$5,MOD($H16,Details!$B$8-1))*10*Details!$C$8,""))/Details!$D$8,0) -> 0 | U16: {=SUMPRODUCT(TRANSPOSE(Details!$D$4:$D$8),$P16:$T16)/Details!$D$9} -> 0.17948718 | V16: {=Details!$D$9-SUMPRODUCT(TRANSPOSE(Details!$D$4:$D$8),$P16:$T16)-$I16} -> 790 | X16: {=LevelUpgradeCost($E16)} -> 3503540000 | Y16: =F16 -> 1 | AA16: =$H16*1000+$E16 -> 3250 | AB16: =RANK($AA16,$AA$3:$AA$47)+COUNTIF($AA$3:$AA16,AA16)-1 -> 19 | AC16: {=IFERROR(_xlfn.IFS($AB16<8,1,$AB16<15,2,$AB16<21,3),"")} -> 3 | AE16: https://encrypted-tbn0.gstatic.com/images?q=tbn:ANd9GcSC1rp-0lIuUyVvSi8kN_vJnr_Ln4mF4lh4zg&s | AF16: =" " | AG16: =" " | AI16: Anubeast
A17: {=GetMutationLevel(B17)} | B17: Battereina | C17: Electricity | D17: Attack | E17: 250 | F17: {=IsUpgradable(E17)} -> 1 | G17: =INT(H17) -> 4 | H17: 4 | I17: 0 | J17: 1 | K17: 1 | L17: 1 | M17: =IF($G17>3,"Max","") -> Max | N17: =IF(H17=5,10,"") | P17: =IFERROR(CHOOSE(IF($H17>=Details!$B$4,1,2),Details!$D$4,IF($H17>Details!$B$4-1,IF($H17<1,$H17,MOD($H17,Details!$B$4-1))*10*Details!$C$4,""))/Details!$D$4,0) -> 1 | Q17: =IFERROR(CHOOSE(IF($H17>=Details!$B$5,1,2),Details!$D$5,IF($H17>Details!$B$5-1,IF($H17<1,Details!$G$4,MOD($H17,Details!$B$5-1))*10*Details!$C$5,""))/Details!$D$5,0) -> 1 | R17: =IFERROR(CHOOSE(IF($H17>=Details!$B$6,1,2),Details!$D$6,IF($H17>Details!$B$6-1,IF($H17<1,Details!$G$5,MOD($H17,Details!$B$6-1))*10*Details!$C$6,""))/Details!$D$6,0) -> 1 | S17: =IFERROR(CHOOSE(IF($H17>=Details!$B$7,1,2),Details!$D$7,IF($H17>Details!$B$7-1,IF($H17<1,Details!$G$5,MOD($H17,Details!$B$7-1))*10*Details!$C$7,""))/Details!$D$7,0) -> 1 | T17: =IFERROR(CHOOSE(IF($H17>=Details!$B$8,1,2),Details!$D$8,IF($H17>Details!$B$8-1,IF($H17<1,Details!$G$5,MOD($H17,Details!$B$8-1))*10*Details!$C$8,""))/Details!$D$8,0) -> 0 | U17: {=SUMPRODUCT(TRANSPOSE(Details!$D$4:$D$8),$P17:$T17)/Details!$D$9} -> 0.48717949 | V17: {=Details!$D$9-SUMPRODUCT(TRANSPOSE(Details!$D$4:$D$8),$P17:$T17)-$I17} -> 500 | X17: {=LevelUpgradeCost($E17)} -> 3503540000 | Y17: =F17 -> 1 | AA17: =$H17*1000+$E17 -> 4250 | AB17: =RANK($AA17,$AA$3:$AA$47)+COUNTIF($AA$3:$AA17,AA17)-1 -> 15 | AC17: {=IFERROR(_xlfn.IFS($AB17<8,1,$AB17<15,2,$AB17<21,3),"")} -> 3 | AE17: https://encrypted-tbn0.gstatic.com/images?q=tbn:ANd9GcQaumzt62POzCPWE5kNVnUA5j6pKVetbogSOJqvW2HU&s | AF17: https://encrypted-tbn0.gstatic.com/images?q=tbn:ANd9GcTun-SMpIMKagR2SMRlAysEcjxhO7sD6Nq3IQ&s | AG17: =" " | AI17: Ampereina
A18: {=GetMutationLevel(B18)} | B18: Fulgairy | C18: Electricity | D18: Defend | E18: 230 | F18: {=IsUpgradable(E18)} -> 1 | G18: =INT(H18) -> 3 | H18: 3.1 | I18: 0 | J18: 5 | K18: 5 | L18: 10 | M18: =IF($G18>3,"Max","") | N18: =IF(H18=5,10,"") | P18: =IFERROR(CHOOSE(IF($H18>=Details!$B$4,1,2),Details!$D$4,IF($H18>Details!$B$4-1,IF($H18<1,$H18,MOD($H18,Details!$B$4-1))*10*Details!$C$4,""))/Details!$D$4,0) -> 1 | Q18: =IFERROR(CHOOSE(IF($H18>=Details!$B$5,1,2),Details!$D$5,IF($H18>Details!$B$5-1,IF($H18<1,Details!$G$4,MOD($H18,Details!$B$5-1))*10*Details!$C$5,""))/Details!$D$5,0) -> 1 | R18: =IFERROR(CHOOSE(IF($H18>=Details!$B$6,1,2),Details!$D$6,IF($H18>Details!$B$6-1,IF($H18<1,Details!$G$5,MOD($H18,Details!$B$6-1))*10*Details!$C$6,""))/Details!$D$6,0) -> 1 | S18: =IFERROR(CHOOSE(IF($H18>=Details!$B$7,1,2),Details!$D$7,IF($H18>Details!$B$7-1,IF($H18<1,Details!$G$5,MOD($H18,Details!$B$7-1))*10*Details!$C$7,""))/Details!$D$7,0) -> 0.2 | T18: =IFERROR(CHOOSE(IF($H18>=Details!$B$8,1,2),Details!$D$8,IF($H18>Details!$B$8-1,IF($H18<1,Details!$G$5,MOD($H18,Details!$B$8-1))*10*Details!$C$8,""))/Details!$D$8,0) -> 0 | U18: {=SUMPRODUCT(TRANSPOSE(Details!$D$4:$D$8),$P18:$T18)/Details!$D$9} -> 0.24102564 | V18: {=Details!$D$9-SUMPRODUCT(TRANSPOSE(Details!$D$4:$D$8),$P18:$T18)-$I18} -> 740 | X18: {=LevelUpgradeCost($E18)} -> 4771140000 | Y18: =F18 -> 1 | AA18: =$H18*1000+$E18 -> 3330 | AB18: =RANK($AA18,$AA$3:$AA$47)+COUNTIF($AA$3:$AA18,AA18)-1 -> 17 | AC18: {=IFERROR(_xlfn.IFS($AB18<8,1,$AB18<15,2,$AB18<21,3),"")} -> 3 | AE18: https://encrypted-tbn0.gstatic.com/images?q=tbn:ANd9GcRvhKm8Syu_29_yraif6I_ybijQhVUhvDmMNg&s | AF18: https://encrypted-tbn0.gstatic.com/images?q=tbn:ANd9GcSNLJe_mmX76tcOcm93Zzrq-x4btMmg4l1csw&s | AG18: =" " | AI18: Keraunosaur
A19: {=GetMutationLevel(B19)} | B19: Blazeal | C19: Fire | D19: Attack | E19: 250 | F19: {=IsUpgradable(E19)} -> 1 | G19: =INT(H19) -> 3 | H19: 3 | I19: 10 | J19: 15 | K19: 10 | L19: 15 | M19: =IF($G19>3,"Max","") | N19: =IF(H19=5,10,"") | P19: =IFERROR(CHOOSE(IF($H19>=Details!$B$4,1,2),Details!$D$4,IF($H19>Details!$B$4-1,IF($H19<1,$H19,MOD($H19,Details!$B$4-1))*10*Details!$C$4,""))/Details!$D$4,0) -> 1 | Q19: =IFERROR(CHOOSE(IF($H19>=Details!$B$5,1,2),Details!$D$5,IF($H19>Details!$B$5-1,IF($H19<1,Details!$G$4,MOD($H19,Details!$B$5-1))*10*Details!$C$5,""))/Details!$D$5,0) -> 1 | R19: =IFERROR(CHOOSE(IF($H19>=Details!$B$6,1,2),Details!$D$6,IF($H19>Details!$B$6-1,IF($H19<1,Details!$G$5,MOD($H19,Details!$B$6-1))*10*Details!$C$6,""))/Details!$D$6,0) -> 1 | S19: =IFERROR(CHOOSE(IF($H19>=Details!$B$7,1,2),Details!$D$7,IF($H19>Details!$B$7-1,IF($H19<1,Details!$G$5,MOD($H19,Details!$B$7-1))*10*Details!$C$7,""))/Details!$D$7,0) -> 0 | T19: =IFERROR(CHOOSE(IF($H19>=Details!$B$8,1,2),Details!$D$8,IF($H19>Details!$B$8-1,IF($H19<1,Details!$G$5,MOD($H19,Details!$B$8-1))*10*Details!$C$8,""))/Details!$D$8,0) -> 0 | U19: {=SUMPRODUCT(TRANSPOSE(Details!$D$4:$D$8),$P19:$T19)/Details!$D$9} -> 0.17948718 | V19: {=Details!$D$9-SUMPRODUCT(TRANSPOSE(Details!$D$4:$D$8),$P19:$T19)-$I19} -> 790 | X19: {=LevelUpgradeCost($E19)} -> 3503540000 | Y19: =F19 -> 1 | AA19: =$H19*1000+$E19 -> 3250 | AB19: =RANK($AA19,$AA$3:$AA$47)+COUNTIF($AA$3:$AA19,AA19)-1 -> 20 | AC19: {=IFERROR(_xlfn.IFS($AB19<8,1,$AB19<15,2,$AB19<21,3),"")} -> 3 | AE19: https://encrypted-tbn0.gstatic.com/images?q=tbn:ANd9GcRsDMtJC3uCFkue3lLpIZqf7OpQgR7XoKOS8g&s | AF19: https://encrypted-tbn0.gstatic.com/images?q=tbn:ANd9GcTc2Arfa7L5NJadx_WdnWjGTYRLP6bgvNMsDUbraRNI&s | AG19: =" " | AI19: Wildfuror
A20: {=GetMutationLevel(B20)} | B20: Pipistrigoi | C20: Fire | D20: Attack | E20: 270 | F20: {=IsUpgradable(E20)} -> 1 | G20: =INT(H20) -> 4 | H20: 4.1 | I20: 13 | J20: 15 | K20: 15 | L20: 15 | M20: =IF($G20>3,"Max","") -> Max | N20: =IF(H20=5,10,"") | P20: =IFERROR(CHOOSE(IF($H20>=Details!$B$4,1,2),Details!$D$4,IF($H20>Details!$B$4-1,IF($H20<1,$H20,MOD($H20,Details!$B$4-1))*10*Details!$C$4,""))/Details!$D$4,0) -> 1 | Q20: =IFERROR(CHOOSE(IF($H20>=Details!$B$5,1,2),Details!$D$5,IF($H20>Details!$B$5-1,IF($H20<1,Details!$G$4,MOD($H20,Details!$B$5-1))*10*Details!$C$5,""))/Details!$D$5,0) -> 1 | R20: =IFERROR(CHOOSE(IF($H20>=Details!$B$6,1,2),Details!$D$6,IF($H20>Details!$B$6-1,IF($H20<1,Details!$G$5,MOD($H20,Details!$B$6-1))*10*Details!$C$6,""))/Details!$D$6,0) -> 1 | S20: =IFERROR(CHOOSE(IF($H20>=Details!$B$7,1,2),Details!$D$7,IF($H20>Details!$B$7-1,IF($H20<1,Details!$G$5,MOD($H20,Details!$B$7-1))*10*Details!$C$7,""))/Details!$D$7,0) -> 1 | T20: =IFERROR(CHOOSE(IF($H20>=Details!$B$8,1,2),Details!$D$8,IF($H20>Details!$B$8-1,IF($H20<1,Details!$G$5,MOD($H20,Details!$B$8-1))*10*Details!$C$8,""))/Details!$D$8,0) -> 0.2 | U20: {=SUMPRODUCT(TRANSPOSE(Details!$D$4:$D$8),$P20:$T20)/Details!$D$9} -> 0.58974359 | V20: {=Details!$D$9-SUMPRODUCT(TRANSPOSE(Details!$D$4:$D$8),$P20:$T20)-$I20} -> 387 | X20: {=LevelUpgradeCost($E20)} -> 1515640000 | Y20: =F20 -> 1 | AA20: =$H20*1000+$E20 -> 4370 | AB20: =RANK($AA20,$AA$3:$AA$47)+COUNTIF($AA$3:$AA20,AA20)-1 -> 9 | AC20: {=IFERROR(_xlfn.IFS($AB20<8,1,$AB20<15,2,$AB20<21,3),"")} -> 2 | AE20: https://encrypted-tbn0.gstatic.com/images?q=tbn:ANd9GcSSdARGNHB_mPJlsb0v4ULv5HaXw2movjzNTNSrkzsi&s | AF20: =" " | AG20: =" " | AI20: Azurostrigoi
A21: {=GetMutationLevel(B21)} | B21: Fingenue | C21: Water | D21: Attack | E21: 200 | F21: {=IsUpgradable(E21)} -> 1 | G21: =INT(H21) -> 2 | H21: 2 | I21: 13 | J21: 5 | K21: 1 | L21: 5 | M21: =IF($G21>3,"Max","") | N21: =IF(H21=5,10,"") | P21: =IFERROR(CHOOSE(IF($H21>=Details!$B$4,1,2),Details!$D$4,IF($H21>Details!$B$4-1,IF($H21<1,$H21,MOD($H21,Details!$B$4-1))*10*Details!$C$4,""))/Details!$D$4,0) -> 1 | Q21: =IFERROR(CHOOSE(IF($H21>=Details!$B$5,1,2),Details!$D$5,IF($H21>Details!$B$5-1,IF($H21<1,Details!$G$4,MOD($H21,Details!$B$5-1))*10*Details!$C$5,""))/Details!$D$5,0) -> 1 | R21: =IFERROR(CHOOSE(IF($H21>=Details!$B$6,1,2),Details!$D$6,IF($H21>Details!$B$6-1,IF($H21<1,Details!$G$5,MOD($H21,Details!$B$6-1))*10*Details!$C$6,""))/Details!$D$6,0) -> 0 | S21: =IFERROR(CHOOSE(IF($H21>=Details!$B$7,1,2),Details!$D$7,IF($H21>Details!$B$7-1,IF($H21<1,Details!$G$5,MOD($H21,Details!$B$7-1))*10*Details!$C$7,""))/Details!$D$7,0) -> 0 | T21: =IFERROR(CHOOSE(IF($H21>=Details!$B$8,1,2),Details!$D$8,IF($H21>Details!$B$8-1,IF($H21<1,Details!$G$5,MOD($H21,Details!$B$8-1))*10*Details!$C$8,""))/Details!$D$8,0) -> 0 | U21: {=SUMPRODUCT(TRANSPOSE(Details!$D$4:$D$8),$P21:$T21)/Details!$D$9} -> 0.076923077 | V21: {=Details!$D$9-SUMPRODUCT(TRANSPOSE(Details!$D$4:$D$8),$P21:$T21)-$I21} -> 887 | X21: {=LevelUpgradeCost($E21)} -> 5796240000 | Y21: =F21 -> 1 | AA21: =$H21*1000+$E21 -> 2200 | AB21: =RANK($AA21,$AA$3:$AA$47)+COUNTIF($AA$3:$AA21,AA21)-1 -> 31 | AC21: {=IFERROR(_xlfn.IFS($AB21<8,1,$AB21<15,2,$AB21<21,3),"")} | AE21: https://encrypted-tbn0.gstatic.com/images?q=tbn:ANd9GcQMvgcplGCQCmIPq5ypILKf8v4mBVwxsMgKdg&s | AF21: https://encrypted-tbn0.gstatic.com/images?q=tbn:ANd9GcQK8ZtDU3nBBFFGN2vhlNn2ACJuBBoGsnFHZC7On4Gb&s | AG21: =" " | AI21: Finnabelle
A22: {=GetMutationLevel(B22)} | B22: Dolphriend | C22: Water | D22: Defend | E22: 210 | F22: {=IsUpgradable(E22)} -> 1 | G22: =INT(H22) -> 2 | H22: 2.4 | I22: 1 | J22: 1 | K22: 1 | L22: 1 | M22: =IF($G22>3,"Max","") | N22: =IF(H22=5,10,"") | P22: =IFERROR(CHOOSE(IF($H22>=Details!$B$4,1,2),Details!$D$4,IF($H22>Details!$B$4-1,IF($H22<1,$H22,MOD($H22,Details!$B$4-1))*10*Details!$C$4,""))/Details!$D$4,0) -> 1 | Q22: =IFERROR(CHOOSE(IF($H22>=Details!$B$5,1,2),Details!$D$5,IF($H22>Details!$B$5-1,IF($H22<1,Details!$G$4,MOD($H22,Details!$B$5-1))*10*Details!$C$5,""))/Details!$D$5,0) -> 1 | R22: =IFERROR(CHOOSE(IF($H22>=Details!$B$6,1,2),Details!$D$6,IF($H22>Details!$B$6-1,IF($H22<1,Details!$G$5,MOD($H22,Details!$B$6-1))*10*Details!$C$6,""))/Details!$D$6,0) -> 0.8 | S22: =IFERROR(CHOOSE(IF($H22>=Details!$B$7,1,2),Details!$D$7,IF($H22>Details!$B$7-1,IF($H22<1,Details!$G$5,MOD($H22,Details!$B$7-1))*10*Details!$C$7,""))/Details!$D$7,0) -> 0 | T22: =IFERROR(CHOOSE(IF($H22>=Details!$B$8,1,2),Details!$D$8,IF($H22>Details!$B$8-1,IF($H22<1,Details!$G$5,MOD($H22,Details!$B$8-1))*10*Details!$C$8,""))/Details!$D$8,0) -> 0 | U22: {=SUMPRODUCT(TRANSPOSE(Details!$D$4:$D$8),$P22:$T22)/Details!$D$9} -> 0.15897436 | V22: {=Details!$D$9-SUMPRODUCT(TRANSPOSE(Details!$D$4:$D$8),$P22:$T22)-$I22} -> 819 | X22: {=LevelUpgradeCost($E22)} -> 5541940000 | Y22: =F22 -> 1 | AA22: =$H22*1000+$E22 -> 2610 | AB22: =RANK($AA22,$AA$3:$AA$47)+COUNTIF($AA$3:$AA22,AA22)-1 -> 24 | AC22: {=IFERROR(_xlfn.IFS($AB22<8,1,$AB22<15,2,$AB22<21,3),"")} | AE22: https://encrypted-tbn0.gstatic.com/images?q=tbn:ANd9GcQ5ThIRML8-S9czd3JEMxpMlnMn9UAMwdeiBw&s | AF22: https://encrypted-tbn0.gstatic.com/images?q=tbn:ANd9GcTQp9fQrKVHd_zzyuSxM8QSOjlZsRbJ0lwxrg&s | AG22: =" " | AI22: Adolphonis
A23: {=GetMutationLevel(B23)} | B23: Ninjump | C23: Water | D23: Attack | E23: 160 | F23: {=IsUpgradable(E23)} -> 1 | G23: =INT(H23) -> 2 | H23: 2.3 | I23: 10 | J23: 1 | K23: 1 | L23: 1 | M23: =IF($G23>3,"Max","") | N23: =IF(H23=5,10,"") | P23: =IFERROR(CHOOSE(IF($H23>=Details!$B$4,1,2),Details!$D$4,IF($H23>Details!$B$4-1,IF($H23<1,$H23,MOD($H23,Details!$B$4-1))*10*Details!$C$4,""))/Details!$D$4,0) -> 1 | Q23: =IFERROR(CHOOSE(IF($H23>=Details!$B$5,1,2),Details!$D$5,IF($H23>Details!$B$5-1,IF($H23<1,Details!$G$4,MOD($H23,Details!$B$5-1))*10*Details!$C$5,""))/Details!$D$5,0) -> 1 | R23: =IFERROR(CHOOSE(IF($H23>=Details!$B$6,1,2),Details!$D$6,IF($H23>Details!$B$6-1,IF($H23<1,Details!$G$5,MOD($H23,Details!$B$6-1))*10*Details!$C$6,""))/Details!$D$6,0) -> 0.6 | S23: =IFERROR(CHOOSE(IF($H23>=Details!$B$7,1,2),Details!$D$7,IF($H23>Details!$B$7-1,IF($H23<1,Details!$G$5,MOD($H23,Details!$B$7-1))*10*Details!$C$7,""))/Details!$D$7,0) -> 0 | T23: =IFERROR(CHOOSE(IF($H23>=Details!$B$8,1,2),Details!$D$8,IF($H23>Details!$B$8-1,IF($H23<1,Details!$G$5,MOD($H23,Details!$B$8-1))*10*Details!$C$8,""))/Details!$D$8,0) -> 0 | U23: {=SUMPRODUCT(TRANSPOSE(Details!$D$4:$D$8),$P23:$T23)/Details!$D$9} -> 0.13846154 | V23: {=Details!$D$9-SUMPRODUCT(TRANSPOSE(Details!$D$4:$D$8),$P23:$T23)-$I23} -> 830 | X23: {=LevelUpgradeCost($E23)} -> 6299740000 | Y23: =F23 -> 1 | AA23: =$H23*1000+$E23 -> 2460 | AB23: =RANK($AA23,$AA$3:$AA$47)+COUNTIF($AA$3:$AA23,AA23)-1 -> 26 | AC23: {=IFERROR(_xlfn.IFS($AB23<8,1,$AB23<15,2,$AB23<21,3),"")} | AE23: https://encrypted-tbn0.gstatic.com/images?q=tbn:ANd9GcQlW5YoM4c6bArAuIb7UxI-VfUI9GmBp85Qig&s | AF23: https://encrypted-tbn0.gstatic.com/images?q=tbn:ANd9GcRXczs_Bjhslhr7Mf2HENU6MTyGpz0RJEMjNA&s | AG23: =" " | AI23: Bufonobi | AJ23: Shadowkaeru
A24: {=GetMutationLevel(B24)} | B24: Surveilynx | C24: Wood | D24: Attack | E24: 230 | F24: {=IsUpgradable(E24)} -> 1 | G24: =INT(H24) -> 2 | H24: 2 | I24: 0 | J24: 10 | K24: 10 | L24: 10 | M24: =IF($G24>3,"Max","") | N24: =IF(H24=5,10,"") | P24: =IFERROR(CHOOSE(IF($H24>=Details!$B$4,1,2),Details!$D$4,IF($H24>Details!$B$4-1,IF($H24<1,$H24,MOD($H24,Details!$B$4-1))*10*Details!$C$4,""))/Details!$D$4,0) -> 1 | Q24: =IFERROR(CHOOSE(IF($H24>=Details!$B$5,1,2),Details!$D$5,IF($H24>Details!$B$5-1,IF($H24<1,Details!$G$4,MOD($H24,Details!$B$5-1))*10*Details!$C$5,""))/Details!$D$5,0) -> 1 | R24: =IFERROR(CHOOSE(IF($H24>=Details!$B$6,1,2),Details!$D$6,IF($H24>Details!$B$6-1,IF($H24<1,Details!$G$5,MOD($H24,Details!$B$6-1))*10*Details!$C$6,""))/Details!$D$6,0) -> 0 | S24: =IFERROR(CHOOSE(IF($H24>=Details!$B$7,1,2),Details!$D$7,IF($H24>Details!$B$7-1,IF($H24<1,Details!$G$5,MOD($H24,Details!$B$7-1))*10*Details!$C$7,""))/Details!$D$7,0) -> 0 | T24: =IFERROR(CHOOSE(IF($H24>=Details!$B$8,1,2),Details!$D$8,IF($H24>Details!$B$8-1,IF($H24<1,Details!$G$5,MOD($H24,Details!$B$8-1))*10*Details!$C$8,""))/Details!$D$8,0) -> 0 | U24: {=SUMPRODUCT(TRANSPOSE(Details!$D$4:$D$8),$P24:$T24)/Details!$D$9} -> 0.076923077 | V24: {=Details!$D$9-SUMPRODUCT(TRANSPOSE(Details!$D$4:$D$8),$P24:$T24)-$I24} -> 900 | X24: {=LevelUpgradeCost($E24)} -> 4771140000 | Y24: =F24 -> 1 | AA24: =$H24*1000+$E24 -> 2230 | AB24: =RANK($AA24,$AA$3:$AA$47)+COUNTIF($AA$3:$AA24,AA24)-1 -> 30 | AC24: {=IFERROR(_xlfn.IFS($AB24<8,1,$AB24<15,2,$AB24<21,3),"")} | AE24: https://encrypted-tbn0.gstatic.com/images?q=tbn:ANd9GcS2Z4TkKenIldVD1AQ7o1ftBU6pG9zKRz-FKA&s | AF24: https://encrypted-tbn0.gstatic.com/images?q=tbn:ANd9GcQt6lIf0Em_f_DT0VurOVsujswJCEmGOpJk4N6txfed&s | AG24: =" " | AI24: Camouflynx
A25: {=GetMutationLevel(B25)} | B25: Salamantis | C25: Wood | D25: Attack | E25: 200 | F25: {=IsUpgradable(E25)} -> 1 | G25: =INT(H25) -> 2 | H25: 2.3 | I25: 0 | J25: 1 | K25: 1 | L25: 1 | M25: =IF($G25>3,"Max","") | N25: =IF(H25=5,10,"") | P25: =IFERROR(CHOOSE(IF($H25>=Details!$B$4,1,2),Details!$D$4,IF($H25>Details!$B$4-1,IF($H25<1,$H25,MOD($H25,Details!$B$4-1))*10*Details!$C$4,""))/Details!$D$4,0) -> 1 | Q25: =IFERROR(CHOOSE(IF($H25>=Details!$B$5,1,2),Details!$D$5,IF($H25>Details!$B$5-1,IF($H25<1,Details!$G$4,MOD($H25,Details!$B$5-1))*10*Details!$C$5,""))/Details!$D$5,0) -> 1 | R25: =IFERROR(CHOOSE(IF($H25>=Details!$B$6,1,2),Details!$D$6,IF($H25>Details!$B$6-1,IF($H25<1,Details!$G$5,MOD($H25,Details!$B$6-1))*10*Details!$C$6,""))/Details!$D$6,0) -> 0.6 | S25: =IFERROR(CHOOSE(IF($H25>=Details!$B$7,1,2),Details!$D$7,IF($H25>Details!$B$7-1,IF($H25<1,Details!$G$5,MOD($H25,Details!$B$7-1))*10*Details!$C$7,""))/Details!$D$7,0) -> 0 | T25: =IFERROR(CHOOSE(IF($H25>=Details!$B$8,1,2),Details!$D$8,IF($H25>Details!$B$8-1,IF($H25<1,Details!$G$5,MOD($H25,Details!$B$8-1))*10*Details!$C$8,""))/Details!$D$8,0) -> 0 | U25: {=SUMPRODUCT(TRANSPOSE(Details!$D$4:$D$8),$P25:$T25)/Details!$D$9} -> 0.13846154 | V25: {=Details!$D$9-SUMPRODUCT(TRANSPOSE(Details!$D$4:$D$8),$P25:$T25)-$I25} -> 840 | X25: {=LevelUpgradeCost($E25)} -> 5796240000 | Y25: =F25 -> 1 | AA25: =$H25*1000+$E25 -> 2500 | AB25: =RANK($AA25,$AA$3:$AA$47)+COUNTIF($AA$3:$AA25,AA25)-1 -> 25 | AC25: {=IFERROR(_xlfn.IFS($AB25<8,1,$AB25<15,2,$AB25<21,3),"")} | AE25: https://encrypted-tbn0.gstatic.com/images?q=tbn:ANd9GcSPFSxpzP3XhhfdRhxvv_Oi86DkexX6yjZrRA&s | AG25: =" " | AI25: Silvaurus
A26: {=GetMutationLevel(B26)} | B26: Regalion | C26: Water | D26: Defend | E26: 200 | F26: {=IsUpgradable(E26)} -> 1 | G26: =INT(H26) -> 2 | H26: 2.2 | I26: 11 | J26: 10 | K26: 10 | L26: 10 | M26: =IF($G26>3,"Max","") | N26: =IF(H26=5,10,"") | P26: =IFERROR(CHOOSE(IF($H26>=Details!$B$4,1,2),Details!$D$4,IF($H26>Details!$B$4-1,IF($H26<1,$H26,MOD($H26,Details!$B$4-1))*10*Details!$C$4,""))/Details!$D$4,0) -> 1 | Q26: =IFERROR(CHOOSE(IF($H26>=Details!$B$5,1,2),Details!$D$5,IF($H26>Details!$B$5-1,IF($H26<1,Details!$G$4,MOD($H26,Details!$B$5-1))*10*Details!$C$5,""))/Details!$D$5,0) -> 1 | R26: =IFERROR(CHOOSE(IF($H26>=Details!$B$6,1,2),Details!$D$6,IF($H26>Details!$B$6-1,IF($H26<1,Details!$G$5,MOD($H26,Details!$B$6-1))*10*Details!$C$6,""))/Details!$D$6,0) -> 0.4 | S26: =IFERROR(CHOOSE(IF($H26>=Details!$B$7,1,2),Details!$D$7,IF($H26>Details!$B$7-1,IF($H26<1,Details!$G$5,MOD($H26,Details!$B$7-1))*10*Details!$C$7,""))/Details!$D$7,0) -> 0 | T26: =IFERROR(CHOOSE(IF($H26>=Details!$B$8,1,2),Details!$D$8,IF($H26>Details!$B$8-1,IF($H26<1,Details!$G$5,MOD($H26,Details!$B$8-1))*10*Details!$C$8,""))/Details!$D$8,0) -> 0 | U26: {=SUMPRODUCT(TRANSPOSE(Details!$D$4:$D$8),$P26:$T26)/Details!$D$9} -> 0.11794872 | V26: {=Details!$D$9-SUMPRODUCT(TRANSPOSE(Details!$D$4:$D$8),$P26:$T26)-$I26} -> 849 | X26: {=LevelUpgradeCost($E26)} -> 5796240000 | Y26: =F26 -> 1 | AA26: =$H26*1000+$E26 -> 2400 | AB26: =RANK($AA26,$AA$3:$AA$47)+COUNTIF($AA$3:$AA26,AA26)-1 -> 29 | AC26: {=IFERROR(_xlfn.IFS($AB26<8,1,$AB26<15,2,$AB26<21,3),"")} | AE26: https://encrypted-tbn0.gstatic.com/images?q=tbn:ANd9GcToQuTLjFC_oynclPIY9tWM7qAaMIPbmzTn2Q&s | AF26: https://encrypted-tbn0.gstatic.com/images?q=tbn:ANd9GcS0uWep-9VXcdMd6qSpdASqYR42mG4SmBsCjw&s | AG26: =" " | AI26: Lionarch
A27: {=GetMutationLevel(B27)} | B27: Mantleray | C27: Electricity | D27: Attack | E27: 230 | F27: {=IsUpgradable(E27)} -> 1 | G27: =INT(H27) -> 2 | H27: 2.4 | I27: 3 | J27: 4 | K27: 1 | L27: 1 | M27: =IF($G27>3,"Max","") | N27: =IF(H27=5,10,"") | P27: =IFERROR(CHOOSE(IF($H27>=Details!$B$4,1,2),Details!$D$4,IF($H27>Details!$B$4-1,IF($H27<1,$H27,MOD($H27,Details!$B$4-1))*10*Details!$C$4,""))/Details!$D$4,0) -> 1 | Q27: =IFERROR(CHOOSE(IF($H27>=Details!$B$5,1,2),Details!$D$5,IF($H27>Details!$B$5-1,IF($H27<1,Details!$G$4,MOD($H27,Details!$B$5-1))*10*Details!$C$5,""))/Details!$D$5,0) -> 1 | R27: =IFERROR(CHOOSE(IF($H27>=Details!$B$6,1,2),Details!$D$6,IF($H27>Details!$B$6-1,IF($H27<1,Details!$G$5,MOD($H27,Details!$B$6-1))*10*Details!$C$6,""))/Details!$D$6,0) -> 0.8 | S27: =IFERROR(CHOOSE(IF($H27>=Details!$B$7,1,2),Details!$D$7,IF($H27>Details!$B$7-1,IF($H27<1,Details!$G$5,MOD($H27,Details!$B$7-1))*10*Details!$C$7,""))/Details!$D$7,0) -> 0 | T27: =IFERROR(CHOOSE(IF($H27>=Details!$B$8,1,2),Details!$D$8,IF($H27>Details!$B$8-1,IF($H27<1,Details!$G$5,MOD($H27,Details!$B$8-1))*10*Details!$C$8,""))/Details!$D$8,0) -> 0 | U27: {=SUMPRODUCT(TRANSPOSE(Details!$D$4:$D$8),$P27:$T27)/Details!$D$9} -> 0.15897436 | V27: {=Details!$D$9-SUMPRODUCT(TRANSPOSE(Details!$D$4:$D$8),$P27:$T27)-$I27} -> 817 | X27: {=LevelUpgradeCost($E27)} -> 4771140000 | Y27: =F27 -> 1 | AA27: =$H27*1000+$E27 -> 2630 | AB27: =RANK($AA27,$AA$3:$AA$47)+COUNTIF($AA$3:$AA27,AA27)-1 -> 23 | AC27: {=IFERROR(_xlfn.IFS($AB27<8,1,$AB27<15,2,$AB27<21,3),"")} | AE27: https://encrypted-tbn0.gstatic.com/images?q=tbn:ANd9GcSWhzppoZXwh-zBnWIY3GFkIp0x0kc0hAzG0A&s | AF27: =" " | AG27: =" " | AI27: Sorceray
A28: {=GetMutationLevel(B28)} | B28: Oleana | C28: Wood | D28: Attack | E28: 260 | F28: {=IsUpgradable(E28)} -> 1 | G28: =INT(H28) -> 5 | H28: 5 | I28: 128 | J28: 1 | K28: 1 | L28: 1 | M28: =IF($G28>3,"Max","") -> Max | N28: =IF(H28=5,10,"") -> 10 | P28: =IFERROR(CHOOSE(IF($H28>=Details!$B$4,1,2),Details!$D$4,IF($H28>Details!$B$4-1,IF($H28<1,$H28,MOD($H28,Details!$B$4-1))*10*Details!$C$4,""))/Details!$D$4,0) -> 1 | Q28: =IFERROR(CHOOSE(IF($H28>=Details!$B$5,1,2),Details!$D$5,IF($H28>Details!$B$5-1,IF($H28<1,Details!$G$4,MOD($H28,Details!$B$5-1))*10*Details!$C$5,""))/Details!$D$5,0) -> 1 | R28: =IFERROR(CHOOSE(IF($H28>=Details!$B$6,1,2),Details!$D$6,IF($H28>Details!$B$6-1,IF($H28<1,Details!$G$5,MOD($H28,Details!$B$6-1))*10*Details!$C$6,""))/Details!$D$6,0) -> 1 | S28: =IFERROR(CHOOSE(IF($H28>=Details!$B$7,1,2),Details!$D$7,IF($H28>Details!$B$7-1,IF($H28<1,Details!$G$5,MOD($H28,Details!$B$7-1))*10*Details!$C$7,""))/Details!$D$7,0) -> 1 | T28: =IFERROR(CHOOSE(IF($H28>=Details!$B$8,1,2),Details!$D$8,IF($H28>Details!$B$8-1,IF($H28<1,Details!$G$5,MOD($H28,Details!$B$8-1))*10*Details!$C$8,""))/Details!$D$8,0) -> 1 | U28: {=SUMPRODUCT(TRANSPOSE(Details!$D$4:$D$8),$P28:$T28)/Details!$D$9} -> 1 | V28: {=Details!$D$9-SUMPRODUCT(TRANSPOSE(Details!$D$4:$D$8),$P28:$T28)-$I28} -> -128 | X28: {=LevelUpgradeCost($E28)} -> 2616040000 | Y28: =F28 -> 1 | AA28: =$H28*1000+$E28 -> 5260 | AB28: =RANK($AA28,$AA$3:$AA$47)+COUNTIF($AA$3:$AA28,AA28)-1 -> 7 | AC28: {=IFERROR(_xlfn.IFS($AB28<8,1,$AB28<15,2,$AB28<21,3),"")} -> 1 | AE28: https://encrypted-tbn0.gstatic.com/images?q=tbn:ANd9GcQ02wmDjsAMofj1ObwwNW6Vhl_QQ-LUodGIKA&s | AF28: =" " | AG28: =" "
A29: {=GetMutationLevel(B29)} | B29: Spookaboo | C29: Fire | D29: Attack | E29: 230 | F29: {=IsUpgradable(E29)} -> 1 | G29: =INT(H29) -> 5 | H29: 5 | I29: 10 | J29: 1 | K29: 1 | L29: 30 | M29: =IF($G29>3,"Max","") -> Max | N29: =IF(H29=5,10,"") -> 10 | P29: =IFERROR(CHOOSE(IF($H29>=Details!$B$4,1,2),Details!$D$4,IF($H29>Details!$B$4-1,IF($H29<1,$H29,MOD($H29,Details!$B$4-1))*10*Details!$C$4,""))/Details!$D$4,0) -> 1 | Q29: =IFERROR(CHOOSE(IF($H29>=Details!$B$5,1,2),Details!$D$5,IF($H29>Details!$B$5-1,IF($H29<1,Details!$G$4,MOD($H29,Details!$B$5-1))*10*Details!$C$5,""))/Details!$D$5,0) -> 1 | R29: =IFERROR(CHOOSE(IF($H29>=Details!$B$6,1,2),Details!$D$6,IF($H29>Details!$B$6-1,IF($H29<1,Details!$G$5,MOD($H29,Details!$B$6-1))*10*Details!$C$6,""))/Details!$D$6,0) -> 1 | S29: =IFERROR(CHOOSE(IF($H29>=Details!$B$7,1,2),Details!$D$7,IF($H29>Details!$B$7-1,IF($H29<1,Details!$G$5,MOD($H29,Details!$B$7-1))*10*Details!$C$7,""))/Details!$D$7,0) -> 1 | T29: =IFERROR(CHOOSE(IF($H29>=Details!$B$8,1,2),Details!$D$8,IF($H29>Details!$B$8-1,IF($H29<1,Details!$G$5,MOD($H29,Details!$B$8-1))*10*Details!$C$8,""))/Details!$D$8,0) -> 1 | U29: {=SUMPRODUCT(TRANSPOSE(Details!$D$4:$D$8),$P29:$T29)/Details!$D$9} -> 1 | V29: {=Details!$D$9-SUMPRODUCT(TRANSPOSE(Details!$D$4:$D$8),$P29:$T29)-$I29} -> -10 | X29: {=LevelUpgradeCost($E29)} -> 4771140000 | Y29: =F29 -> 1 | AA29: =$H29*1000+$E29 -> 5230 | AB29: =RANK($AA29,$AA$3:$AA$47)+COUNTIF($AA$3:$AA29,AA29)-1 -> 8 | AC29: {=IFERROR(_xlfn.IFS($AB29<8,1,$AB29<15,2,$AB29<21,3),"")} -> 2 | AE29: https://encrypted-tbn0.gstatic.com/images?q=tbn:ANd9GcT29K673YTBvt_EofrppvnWB4sgt43DEq1pTw&s | AF29: =" " | AG29: =" "
A30: {=GetMutationLevel(B30)} | B30: Kungpaw | C30: Water | D30: Defend | E30: 200 | F30: {=IsUpgradable(E30)} -> 1 | G30: =INT(H30) -> 4 | H30: 4.1 | I30: 30 | J30: 1 | K30: 1 | L30: 1 | M30: =IF($G30>3,"Max","") -> Max | N30: =IF(H30=5,10,"") | P30: =IFERROR(CHOOSE(IF($H30>=Details!$B$4,1,2),Details!$D$4,IF($H30>Details!$B$4-1,IF($H30<1,$H30,MOD($H30,Details!$B$4-1))*10*Details!$C$4,""))/Details!$D$4,0) -> 1 | Q30: =IFERROR(CHOOSE(IF($H30>=Details!$B$5,1,2),Details!$D$5,IF($H30>Details!$B$5-1,IF($H30<1,Details!$G$4,MOD($H30,Details!$B$5-1))*10*Details!$C$5,""))/Details!$D$5,0) -> 1 | R30: =IFERROR(CHOOSE(IF($H30>=Details!$B$6,1,2),Details!$D$6,IF($H30>Details!$B$6-1,IF($H30<1,Details!$G$5,MOD($H30,Details!$B$6-1))*10*Details!$C$6,""))/Details!$D$6,0) -> 1 | S30: =IFERROR(CHOOSE(IF($H30>=Details!$B$7,1,2),Details!$D$7,IF($H30>Details!$B$7-1,IF($H30<1,Details!$G$5,MOD($H30,Details!$B$7-1))*10*Details!$C$7,""))/Details!$D$7,0) -> 1 | T30: =IFERROR(CHOOSE(IF($H30>=Details!$B$8,1,2),Details!$D$8,IF($H30>Details!$B$8-1,IF($H30<1,Details!$G$5,MOD($H30,Details!$B$8-1))*10*Details!$C$8,""))/Details!$D$8,0) -> 0.2 | U30: {=SUMPRODUCT(TRANSPOSE(Details!$D$4:$D$8),$P30:$T30)/Details!$D$9} -> 0.58974359 | V30: {=Details!$D$9-SUMPRODUCT(TRANSPOSE(Details!$D$4:$D$8),$P30:$T30)-$I30} -> 370 | X30: {=LevelUpgradeCost($E30)} -> 5796240000 | Y30: =F30 -> 1 | AA30: =$H30*1000+$E30 -> 4300 | AB30: =RANK($AA30,$AA$3:$AA$47)+COUNTIF($AA$3:$AA30,AA30)-1 -> 12 | AC30: {=IFERROR(_xlfn.IFS($AB30<8,1,$AB30<15,2,$AB30<21,3),"")} -> 2 | AE30: https://encrypted-tbn0.gstatic.com/images?q=tbn:ANd9GcRV1HdRcNPUS4HjDBZ2YOXgaMW_I8FgZEP5xg&s | AG30: =" "
A31: {=GetMutationLevel(B31)} | B31: Baboom | C31: Wood | D31: Attack | E31: 240 | F31: {=IsUpgradable(E31)} -> 1 | G31: =INT(H31) -> 3 | H31: 3 | I31: 10 | J31: 5 | K31: 1 | L31: 1 | M31: =IF($G31>3,"Max","") | N31: =IF(H31=5,10,"") | P31: =IFERROR(CHOOSE(IF($H31>=Details!$B$4,1,2),Details!$D$4,IF($H31>Details!$B$4-1,IF($H31<1,$H31,MOD($H31,Details!$B$4-1))*10*Details!$C$4,""))/Details!$D$4,0) -> 1 | Q31: =IFERROR(CHOOSE(IF($H31>=Details!$B$5,1,2),Details!$D$5,IF($H31>Details!$B$5-1,IF($H31<1,Details!$G$4,MOD($H31,Details!$B$5-1))*10*Details!$C$5,""))/Details!$D$5,0) -> 1 | R31: =IFERROR(CHOOSE(IF($H31>=Details!$B$6,1,2),Details!$D$6,IF($H31>Details!$B$6-1,IF($H31<1,Details!$G$5,MOD($H31,Details!$B$6-1))*10*Details!$C$6,""))/Details!$D$6,0) -> 1 | S31: =IFERROR(CHOOSE(IF($H31>=Details!$B$7,1,2),Details!$D$7,IF($H31>Details!$B$7-1,IF($H31<1,Details!$G$5,MOD($H31,Details!$B$7-1))*10*Details!$C$7,""))/Details!$D$7,0) -> 0 | T31: =IFERROR(CHOOSE(IF($H31>=Details!$B$8,1,2),Details!$D$8,IF($H31>Details!$B$8-1,IF($H31<1,Details!$G$5,MOD($H31,Details!$B$8-1))*10*Details!$C$8,""))/Details!$D$8,0) -> 0 | U31: {=SUMPRODUCT(TRANSPOSE(Details!$D$4:$D$8),$P31:$T31)/Details!$D$9} -> 0.17948718 | V31: {=Details!$D$9-SUMPRODUCT(TRANSPOSE(Details!$D$4:$D$8),$P31:$T31)-$I31} -> 790 | X31: {=LevelUpgradeCost($E31)} -> 4211940000 | Y31: =F31 -> 1 | AA31: =$H31*1000+$E31 -> 3240 | AB31: =RANK($AA31,$AA$3:$AA$47)+COUNTIF($AA$3:$AA31,AA31)-1 -> 21 | AC31: {=IFERROR(_xlfn.IFS($AB31<8,1,$AB31<15,2,$AB31<21,3),"")} | AE31: https://encrypted-tbn0.gstatic.com/images?q=tbn:ANd9GcRh7P3oaH_Kq0fni1aOxe3TmDgHULu_Z-UWUg&s | AF31: https://encrypted-tbn0.gstatic.com/images?q=tbn:ANd9GcSQA67-vNrm701vphmHvRKGkJTx2O2gyTi00Q&s | AG31: =" " | AI31: Rumbkey
A32: {=GetMutationLevel(B32)} | B32: Pyregeist | C32: Fire | D32: Defend | F32: {=IsUpgradable(E32)} | G32: =INT(H32) -> 0 | J32: {=IF(E32="","",_xlfn.MAKEARRAY(1,3,_xlfn.LAMBDA(_xlpm.row,_xlpm.col,1)))} | M32: =IF($G32>3,"Max","") | N32: =IF(H32=5,10,"") | P32: =IFERROR(CHOOSE(IF($H32>=Details!$B$4,1,2),Details!$D$4,IF($H32>Details!$B$4-1,IF($H32<1,$H32,MOD($H32,Details!$B$4-1))*10*Details!$C$4,""))/Details!$D$4,0) -> 0 | Q32: =IFERROR(CHOOSE(IF($H32>=Details!$B$5,1,2),Details!$D$5,IF($H32>Details!$B$5-1,IF($H32<1,Details!$G$4,MOD($H32,Details!$B$5-1))*10*Details!$C$5,""))/Details!$D$5,0) -> 0 | R32: =IFERROR(CHOOSE(IF($H32>=Details!$B$6,1,2),Details!$D$6,IF($H32>Details!$B$6-1,IF($H32<1,Details!$G$5,MOD($H32,Details!$B$6-1))*10*Details!$C$6,""))/Details!$D$6,0) -> 0 | S32: =IFERROR(CHOOSE(IF($H32>=Details!$B$7,1,2),Details!$D$7,IF($H32>Details!$B$7-1,IF($H32<1,Details!$G$5,MOD($H32,Details!$B$7-1))*10*Details!$C$7,""))/Details!$D$7,0) -> 0 | T32: =IFERROR(CHOOSE(IF($H32>=Details!$B$8,1,2),Details!$D$8,IF($H32>Details!$B$8-1,IF($H32<1,Details!$G$5,MOD($H32,Details!$B$8-1))*10*Details!$C$8,""))/Details!$D$8,0) -> 0 | U32: {=SUMPRODUCT(TRANSPOSE(Details!$D$4:$D$8),$P32:$T32)/Details!$D$9} -> 0 | V32: {=Details!$D$9-SUMPRODUCT(TRANSPOSE(Details!$D$4:$D$8),$P32:$T32)-$I32} -> 975 | X32: {=LevelUpgradeCost($E32)} -> 6424613700 | Y32: =F32 | AA32: =$H32*1000+$E32 -> 0 | AB32: =RANK($AA32,$AA$3:$AA$47)+COUNTIF($AA$3:$AA32,AA32)-1 -> 34 | AC32: {=IFERROR(_xlfn.IFS($AB32<8,1,$AB32<15,2,$AB32<21,3),"")} | AE32: https://encrypted-tbn0.gstatic.com/images?q=tbn:ANd9GcQxjczIZhaTQV2VukHWlKoJMQ30DrUIwatAEw&s | AF32: =" " | AG32: =" " | AI32: Embergeist
A33: {=GetMutationLevel(B33)} | B33: Thundertooth | C33: Electricity | D33: Attack | E33: 270 | F33: {=IsUpgradable(E33)} -> 1 | G33: =INT(H33) -> 5 | H33: 5 | I33: 0 | J33: {=IF(E33="","",_xlfn.MAKEARRAY(1,3,_xlfn.LAMBDA(_xlpm.row,_xlpm.col,1)))} -> 1 | K33: 1 | L33: 1 | M33: =IF($G33>3,"Max","") -> Max | N33: =IF(H33=5,10,"") -> 10 | P33: =IFERROR(CHOOSE(IF($H33>=Details!$B$4,1,2),Details!$D$4,IF($H33>Details!$B$4-1,IF($H33<1,$H33,MOD($H33,Details!$B$4-1))*10*Details!$C$4,""))/Details!$D$4,0) -> 1 | Q33: =IFERROR(CHOOSE(IF($H33>=Details!$B$5,1,2),Details!$D$5,IF($H33>Details!$B$5-1,IF($H33<1,Details!$G$4,MOD($H33,Details!$B$5-1))*10*Details!$C$5,""))/Details!$D$5,0) -> 1 | R33: =IFERROR(CHOOSE(IF($H33>=Details!$B$6,1,2),Details!$D$6,IF($H33>Details!$B$6-1,IF($H33<1,Details!$G$5,MOD($H33,Details!$B$6-1))*10*Details!$C$6,""))/Details!$D$6,0) -> 1 | S33: =IFERROR(CHOOSE(IF($H33>=Details!$B$7,1,2),Details!$D$7,IF($H33>Details!$B$7-1,IF($H33<1,Details!$G$5,MOD($H33,Details!$B$7-1))*10*Details!$C$7,""))/Details!$D$7,0) -> 1 | T33: =IFERROR(CHOOSE(IF($H33>=Details!$B$8,1,2),Details!$D$8,IF($H33>Details!$B$8-1,IF($H33<1,Details!$G$5,MOD($H33,Details!$B$8-1))*10*Details!$C$8,""))/Details!$D$8,0) -> 1 | U33: {=SUMPRODUCT(TRANSPOSE(Details!$D$4:$D$8),$P33:$T33)/Details!$D$9} -> 1 | V33: {=Details!$D$9-SUMPRODUCT(TRANSPOSE(Details!$D$4:$D$8),$P33:$T33)-$I33} -> 0 | X33: {=LevelUpgradeCost($E33)} -> 1515640000 | Y33: =F33 -> 1 | AA33: =$H33*1000+$E33 -> 5270 | AB33: =RANK($AA33,$AA$3:$AA$47)+COUNTIF($AA$3:$AA33,AA33)-1 -> 6 | AC33: {=IFERROR(_xlfn.IFS($AB33<8,1,$AB33<15,2,$AB33<21,3),"")} -> 1 | AE33: https://encrypted-tbn0.gstatic.com/images?q=tbn:ANd9GcRNSg29kZ5t51s7m9SpGygJKsQow67zLt08qg&s | AF33: https://encrypted-tbn0.gstatic.com/images?q=tbn:ANd9GcQoXkXemCK02vmhKICXcvjchtQ-qvcAc5zyrA&s | AG33: =" " | AI33: Thundermane
A34: {=GetMutationLevel(B34)} | B34: Mammolith | C34: Wood | D34: Defend | F34: {=IsUpgradable(E34)} | G34: =INT(H34) -> 0 | J34: {=IF(E34="","",_xlfn.MAKEARRAY(1,3,_xlfn.LAMBDA(_xlpm.row,_xlpm.col,1)))} | M34: =IF($G34>3,"Max","") | N34: =IF(H34=5,10,"") | P34: =IFERROR(CHOOSE(IF($H34>=Details!$B$4,1,2),Details!$D$4,IF($H34>Details!$B$4-1,IF($H34<1,$H34,MOD($H34,Details!$B$4-1))*10*Details!$C$4,""))/Details!$D$4,0) -> 0 | Q34: =IFERROR(CHOOSE(IF($H34>=Details!$B$5,1,2),Details!$D$5,IF($H34>Details!$B$5-1,IF($H34<1,Details!$G$4,MOD($H34,Details!$B$5-1))*10*Details!$C$5,""))/Details!$D$5,0) -> 0 | R34: =IFERROR(CHOOSE(IF($H34>=Details!$B$6,1,2),Details!$D$6,IF($H34>Details!$B$6-1,IF($H34<1,Details!$G$5,MOD($H34,Details!$B$6-1))*10*Details!$C$6,""))/Details!$D$6,0) -> 0 | S34: =IFERROR(CHOOSE(IF($H34>=Details!$B$7,1,2),Details!$D$7,IF($H34>Details!$B$7-1,IF($H34<1,Details!$G$5,MOD($H34,Details!$B$7-1))*10*Details!$C$7,""))/Details!$D$7,0) -> 0 | T34: =IFERROR(CHOOSE(IF($H34>=Details!$B$8,1,2),Details!$D$8,IF($H34>Details!$B$8-1,IF($H34<1,Details!$G$5,MOD($H34,Details!$B$8-1))*10*Details!$C$8,""))/Details!$D$8,0) -> 0 | U34: {=SUMPRODUCT(TRANSPOSE(Details!$D$4:$D$8),$P34:$T34)/Details!$D$9} -> 0 | V34: {=Details!$D$9-SUMPRODUCT(TRANSPOSE(Details!$D$4:$D$8),$P34:$T34)-$I34} -> 975 | X34: {=LevelUpgradeCost($E34)} -> 6424613700 | Y34: =F34 | AA34: =$H34*1000+$E34 -> 0 | AB34: =RANK($AA34,$AA$3:$AA$47)+COUNTIF($AA$3:$AA34,AA34)-1 -> 35 | AC34: {=IFERROR(_xlfn.IFS($AB34<8,1,$AB34<15,2,$AB34<21,3),"")} | AE34: https://encrypted-tbn0.gstatic.com/images?q=tbn:ANd9GcRR4T5jdtF_LaheoRmg2FLSWS4DS4QhqCFaAg&s | AF34: =" " | AG34: =" " | AI34: Prismalith
A35: {=GetMutationLevel(B35)} | B35: Glacewing | C35: Water | D35: Attack | E35: 280 | F35: {=IsUpgradable(E35)} | G35: =INT(H35) -> 5 | H35: 5 | I35: 0 | J35: 30 | K35: 30 | L35: 30 | M35: =IF($G35>3,"Max","") -> Max | N35: =IF(H35=5,10,"") -> 10 | P35: =IFERROR(CHOOSE(IF($H35>=Details!$B$4,1,2),Details!$D$4,IF($H35>Details!$B$4-1,IF($H35<1,$H35,MOD($H35,Details!$B$4-1))*10*Details!$C$4,""))/Details!$D$4,0) -> 1 | Q35: =IFERROR(CHOOSE(IF($H35>=Details!$B$5,1,2),Details!$D$5,IF($H35>Details!$B$5-1,IF($H35<1,Details!$G$4,MOD($H35,Details!$B$5-1))*10*Details!$C$5,""))/Details!$D$5,0) -> 1 | R35: =IFERROR(CHOOSE(IF($H35>=Details!$B$6,1,2),Details!$D$6,IF($H35>Details!$B$6-1,IF($H35<1,Details!$G$5,MOD($H35,Details!$B$6-1))*10*Details!$C$6,""))/Details!$D$6,0) -> 1 | S35: =IFERROR(CHOOSE(IF($H35>=Details!$B$7,1,2),Details!$D$7,IF($H35>Details!$B$7-1,IF($H35<1,Details!$G$5,MOD($H35,Details!$B$7-1))*10*Details!$C$7,""))/Details!$D$7,0) -> 1 | T35: =IFERROR(CHOOSE(IF($H35>=Details!$B$8,1,2),Details!$D$8,IF($H35>Details!$B$8-1,IF($H35<1,Details!$G$5,MOD($H35,Details!$B$8-1))*10*Details!$C$8,""))/Details!$D$8,0) -> 1 | U35: {=SUMPRODUCT(TRANSPOSE(Details!$D$4:$D$8),$P35:$T35)/Details!$D$9} -> 1 | V35: {=Details!$D$9-SUMPRODUCT(TRANSPOSE(Details!$D$4:$D$8),$P35:$T35)-$I35} -> 0 | X35: {=LevelUpgradeCost($E35)} -> 164440000 | Y35: =F35 | AA35: =$H35*1000+$E35 -> 5280 | AB35: =RANK($AA35,$AA$3:$AA$47)+COUNTIF($AA$3:$AA35,AA35)-1 -> 1 | AC35: {=IFERROR(_xlfn.IFS($AB35<8,1,$AB35<15,2,$AB35<21,3),"")} -> 1 | AE35: https://encrypted-tbn0.gstatic.com/images?q=tbn:ANd9GcTrE4qGrnpy2BMETqUKNyATj-OrXMdX4IeXcQ&s | AF35: https://encrypted-tbn0.gstatic.com/images?q=tbn:ANd9GcSRbCy1ARx2qd0P1rLvdoRvfNqa4pUV20r12A&s | AG35: =" " | AI35: Cryovern
A36: {=GetMutationLevel(B36)} -> 2 | B36: Shadowkaeru | C36: Water | D36: Attack | F36: {=IsUpgradable(E36)} | G36: =INT(H36) -> 0 | J36: {=IF(E36="","",_xlfn.MAKEARRAY(1,3,_xlfn.LAMBDA(_xlpm.row,_xlpm.col,1)))} | M36: =IF($G36>3,"Max","") | N36: =IF(H36=5,10,"") | P36: =IFERROR(CHOOSE(IF($H36>=Details!$B$4,1,2),Details!$D$4,IF($H36>Details!$B$4-1,IF($H36<1,$H36,MOD($H36,Details!$B$4-1))*10*Details!$C$4,""))/Details!$D$4,0) -> 0 | Q36: =IFERROR(CHOOSE(IF($H36>=Details!$B$5,1,2),Details!$D$5,IF($H36>Details!$B$5-1,IF($H36<1,Details!$G$4,MOD($H36,Details!$B$5-1))*10*Details!$C$5,""))/Details!$D$5,0) -> 0 | R36: =IFERROR(CHOOSE(IF($H36>=Details!$B$6,1,2),Details!$D$6,IF($H36>Details!$B$6-1,IF($H36<1,Details!$G$5,MOD($H36,Details!$B$6-1))*10*Details!$C$6,""))/Details!$D$6,0) -> 0 | S36: =IFERROR(CHOOSE(IF($H36>=Details!$B$7,1,2),Details!$D$7,IF($H36>Details!$B$7-1,IF($H36<1,Details!$G$5,MOD($H36,Details!$B$7-1))*10*Details!$C$7,""))/Details!$D$7,0) -> 0 | T36: =IFERROR(CHOOSE(IF($H36>=Details!$B$8,1,2),Details!$D$8,IF($H36>Details!$B$8-1,IF($H36<1,Details!$G$5,MOD($H36,Details!$B$8-1))*10*Details!$C$8,""))/Details!$D$8,0) -> 0 | U36: {=SUMPRODUCT(TRANSPOSE(Details!$D$4:$D$8),$P36:$T36)/Details!$D$9} -> 0 | V36: {=Details!$D$9-SUMPRODUCT(TRANSPOSE(Details!$D$4:$D$8),$P36:$T36)-$I36} -> 975 | X36: {=LevelUpgradeCost($E36)} -> 6424613700 | Y36: =F36 | AA36: =$H36*1000+$E36 -> 0 | AB36: =RANK($AA36,$AA$3:$AA$47)+COUNTIF($AA$3:$AA36,AA36)-1 -> 36 | AC36: {=IFERROR(_xlfn.IFS($AB36<8,1,$AB36<15,2,$AB36<21,3),"")} | AF36: =" " | AG36: =" "
